Workbook

Sheet Indice
A1: Cálculos paso a paso del proyecto final de Análisis de algoritmos
A2: Universidad del Quindío · Corpus: 20 abstracts sobre IA en educación · Cada hoja reproduce con fórmulas un caso del documento técnico.
A4: Convención de colores
A5: Texto azul | B5: Dato de entrada: términos, vectores o tablas que produce el programa Java (no se modifican).
A6: Texto negro | B6: Fórmula de Excel que reproduce el cálculo del algoritmo.
A7: Texto verde | B7: Referencia a otra hoja.
A8: Fondo verde | B8: Resultado que se compara con la salida del programa (columna "Programa Java").
A10: Hoja | B10: Contenido
A11: 1.1 Levenshtein | B11: Subcaso de 7 × 7 términos con la recurrencia D[i][j] (sección 9.1)
A12: 1.1b Levenshtein completo | B12: Matriz de 115 × 94 celdas de los abstracts 11 y 16: D[114][93] = 108
A13: 1.2 Needleman-Wunsch | B13: Subcaso 7 × 7 con +1 / −1 / −1 y el alineamiento (sección 9.2)
A14: 1.2b NW completo | B14: Matriz completa: puntaje F[114][93] = −100
A15: 1.3 TF-IDF coseno | B15: tf, df, idf = log10(20/df), pesos, producto punto, normas y coseno (sección 9.3)
A16: 1.4 Jaccard | B16: Conjuntos A, B, intersección y unión (sección 9.4)
A17: 1.5 GloVe | B17: Promedio de vectores de palabra (100 dimensiones) y coseno (sección 9.5)
... A30: Complejidad | B30: T(n) de cada algoritmo evaluado con los tamaños reales

Sheet 1.1 Levenshtein
A1: Levenshtein: subcaso con los 7 primeros términos de cada abstract
A2: D[i][0] = i, D[0][j] = j; D[i][j] = min(D[i-1][j] + 1, D[i][j-1] + 1, D[i-1][j-1] + costo), costo = 0 si a_i = b_j. Código: Levenshtein.java líneas 24, 28, 34-39.
A4: A \ B | B4: - | C4: emergence | D4: generative | E4: artificial | F4: intelligence | G4: ai | H4: chatgpt | I4: sparked
A5: - | B5: 0 | C5: 1 | D5: 2 | E5: 3 | F5: 4 | G5: 5 | H5: 6 | I5: 7
A6: generative | B6: 1 | C6: =MIN(C5+1,B6+1,B5+IF($A6=C$4,0,1)) -> 1 | D6: =MIN(D5+1,C6+1,C5+IF($A6=D$4,0,1)) -> 1 | E6: =MIN(E5+1,D6+1,D5+IF($A6=E$4,0,1)) -> 2 | F6: =MIN(F5+1,E6+1,E5+IF($A6=F$4,0,1)) -> 3 | G6: =MIN(G5+1,F6+1,F5+IF($A6=G$4,0,1)) -> 4 | H6: =MIN(H5+1,G6+1,G5+IF($A6=H$4,0,1)) -> 5 | I6: =MIN(I5+1,H6+1,H5+IF($A6=I$4,0,1)) -> 6
A7: artificial | B7: 2 | C7: =MIN(C6+1,B7+1,B6+IF($A7=C$4,0,1)) -> 2 | D7: =MIN(D6+1,C7+1,C6+IF($A7=D$4,0,1)) -> 2 | E7: =MIN(E6+1,D7+1,D6+IF($A7=E$4,0,1)) -> 1 | F7: =MIN(F6+1,E7+1,E6+IF($A7=F$4,0,1)) -> 2 | G7: =MIN(G6+1,F7+1,F6+IF($A7=G$4,0,1)) -> 3 | H7: =MIN(H6+1,G7+1,G6+IF($A7=H$4,0,1)) -> 4 | I7: =MIN(I6+1,H7+1,H6+IF($A7=I$4,0,1)) -> 5
A8: intelligence | B8: 3 | C8: =MIN(C7+1,B8+1,B7+IF($A8=C$4,0,1)) -> 3 | D8: =MIN(D7+1,C8+1,C7+IF($A8=D$4,0,1)) -> 3 | E8: =MIN(E7+1,D8+1,D7+IF($A8=E$4,0,1)) -> 2 | F8: =MIN(F7+1,E8+1,E7+IF($A8=F$4,0,1)) -> 1 | G8: =MIN(G7+1,F8+1,F7+IF($A8=G$4,0,1)) -> 2 | H8: =MIN(H7+1,G8+1,G7+IF($A8=H$4,0,1)) -> 3 | I8: =MIN(I7+1,H8+1,H7+IF($A8=I$4,0,1)) -> 4
A9: provides | B9: 4 | C9: =MIN(C8+1,B9+1,B8+IF($A9=C$4,0,1)) -> 4 | D9: =MIN(D8+1,C9+1,C8+IF($A9=D$4,0,1)) -> 4 | E9: =MIN(E8+1,D9+1,D8+IF($A9=E$4,0,1)) -> 3 | F9: =MIN(F8+1,E9+1,E8+IF($A9=F$4,0,1)) -> 2 | G9: =MIN(G8+1,F9+1,F8+IF($A9=G$4,0,1)) -> 2 | H9: =MIN(H8+1,G9+1,G8+IF($A9=H$4,0,1)) -> 3 | I9: =MIN(I8+1,H9+1,H8+IF($A9=I$4,0,1)) -> 4
A10: opportunities | B10: 5 | C10: =MIN(C9+1,B10+1,B9+IF($A10=C$4,0,1)) -> 5 | D10: =MIN(D9+1,C10+1,C9+IF($A10=D$4,0,1)) -> 5 | E10: =MIN(E9+1,D10+1,D9+IF($A10=E$4,0,1)) -> 4 | F10: =MIN(F9+1,E10+1,E9+IF($A10=F$4,0,1)) -> 3 | G10: =MIN(G9+1,F10+1,F9+IF($A10=G$4,0,1)) -> 3 | H10: =MIN(H9+1,G10+1,G9+IF($A10=H$4,0,1)) -> 3 | I10: =MIN(I9+1,H10+1,H9+IF($A10=I$4,0,1)) -> 4
A11: challenges | B11: 6 | C11: =MIN(C10+1,B11+1,B10+IF($A11=C$4,0,1)) -> 6 | D11: =MIN(D10+1,C11+1,C10+IF($A11=D$4,0,1)) -> 6 | E11: =MIN(E10+1,D11+1,D10+IF($A11=E$4,0,1)) -> 5 | F11: =MIN(F10+1,E11+1,E10+IF($A11=F$4,0,1)) -> 4 | G11: =MIN(G10+1,F11+1,F10+IF($A11=G$4,0,1)) -> 4 | H11: =MIN(H10+1,G11+1,G10+IF($A11=H$4,0,1)) -> 4 | I11: =MIN(I10+1,H11+1,H10+IF($A11=I$4,0,1)) -> 4
A12: higher | B12: 7 | C12: =MIN(C11+1,B12+1,B11+IF($A12=C$4,0,1)) -> 7 | D12: =MIN(D11+1,C12+1,C11+IF($A12=D$4,0,1)) -> 7 | E12: =MIN(E11+1,D12+1,D11+IF($A12=E$4,0,1)) -> 6 | F12: =MIN(F11+1,E12+1,E11+IF($A12=F$4,0,1)) -> 5 | G12: =MIN(G11+1,F12+1,F11+IF($A12=G$4,0,1)) -> 5 | H12: =MIN(H11+1,G12+1,G11+IF($A12=H$4,0,1)) -> 5 | I12: =MIN(I11+1,H12+1,H11+IF($A12=I$4,0,1)) -> 5
A14: Distancia D[7][7] | B14: =I12 -> 5 | C14: Programa Java | D14: 5
A15: Similitud = 1 − D / max(n, m) | B15: =1-B14/MAX(7,7) -> 0.28571429 | C15: Programa Java | D15: 0.2857
A17: Abstracts completos (hoja 1.1b): D[114][93] | D17: ='1.1b Levenshtein completo'!B2 -> 108
A18: Similitud de los abstracts completos = 1 − D / 114 | D18: =1-D17/114 -> 0.052631579

Sheet 1.2 Needleman-Wunsch
A1: Needleman-Wunsch: subcaso con los 7 primeros términos (+1 coincidencia, −1 sustitución, −1 hueco)
A2: F[i][0] = −i, F[0][j] = −j; F[i][j] = max(F[i-1][j-1] + s(a_i, b_j), F[i-1][j] − 1, F[i][j-1] − 1). Código: NeedlemanWunsch.java líneas 36-49.
A4: A \ B | B4: - | C4: emergence | D4: generative | E4: artificial | F4: intelligence | G4: ai | H4: chatgpt | I4: sparked
A5: - | B5: 0 | C5: -1 | D5: -2 | E5: -3 | F5: -4 | G5: -5 | H5: -6 | I5: -7
A6: generative | B6: -1 | C6: =MAX(B5+IF($A6=C$4,1,-1),C5-1,B6-1) -> -1 | D6: =MAX(C5+IF($A6=D$4,1,-1),D5-1,C6-1) -> 0 | E6: =MAX(D5+IF($A6=E$4,1,-1),E5-1,D6-1) -> -1 | F6: =MAX(E5+IF($A6=F$4,1,-1),F5-1,E6-1) -> -2 | G6: =MAX(F5+IF($A6=G$4,1,-1),G5-1,F6-1) -> -3 | H6: =MAX(G5+IF($A6=H$4,1,-1),H5-1,G6-1) -> -4 | I6: =MAX(H5+IF($A6=I$4,1,-1),I5-1,H6-1) -> -5
A7: artificial | B7: -2 | C7: =MAX(B6+IF($A7=C$4,1,-1),C6-1,B7-1) -> -2 | D7: =MAX(C6+IF($A7=D$4,1,-1),D6-1,C7-1) -> -1 | E7: =MAX(D6+IF($A7=E$4,1,-1),E6-1,D7-1) -> 1 | F7: =MAX(E6+IF($A7=F$4,1,-1),F6-1,E7-1) -> 0 | G7: =MAX(F6+IF($A7=G$4,1,-1),G6-1,F7-1) -> -1 | H7: =MAX(G6+IF($A7=H$4,1,-1),H6-1,G7-1) -> -2 | I7: =MAX(H6+IF($A7=I$4,1,-1),I6-1,H7-1) -> -3
A8: intelligence | B8: -3 | C8: =MAX(B7+IF($A8=C$4,1,-1),C7-1,B8-1) -> -3 | D8: =MAX(C7+IF($A8=D$4,1,-1),D7-1,C8-1) -> -2 | E8: =MAX(D7+IF($A8=E$4,1,-1),E7-1,D8-1) -> 0 | F8: =MAX(E7+IF($A8=F$4,1,-1),F7-1,E8-1) -> 2 | G8: =MAX(F7+IF($A8=G$4,1,-1),G7-1,F8-1) -> 1 | H8: =MAX(G7+IF($A8=H$4,1,-1),H7-1,G8-1) -> 0 | I8: =MAX(H7+IF($A8=I$4,1,-1),I7-1,H8-1) -> -1
A9: provides | B9: -4 | C9: =MAX(B8+IF($A9=C$4,1,-1),C8-1,B9-1) -> -4 | D9: =MAX(C8+IF($A9=D$4,1,-1),D8-1,C9-1) -> -3 | E9: =MAX(D8+IF($A9=E$4,1,-1),E8-1,D9-1) -> -1 | F9: =MAX(E8+IF($A9=F$4,1,-1),F8-1,E9-1) -> 1 | G9: =MAX(F8+IF($A9=G$4,1,-1),G8-1,F9-1) -> 1 | H9: =MAX(G8+IF($A9=H$4,1,-1),H8-1,G9-1) -> 0 | I9: =MAX(H8+IF($A9=I$4,1,-1),I8-1,H9-1) -> -1
A10: opportunities | B10: -5 | C10: =MAX(B9+IF($A10=C$4,1,-1),C9-1,B10-1) -> -5 | D10: =MAX(C9+IF($A10=D$4,1,-1),D9-1,C10-1) -> -4 | E10: =MAX(D9+IF($A10=E$4,1,-1),E9-1,D10-1) -> -2 | F10: =MAX(E9+IF($A10=F$4,1,-1),F9-1,E10-1) -> 0 | G10: =MAX(F9+IF($A10=G$4,1,-1),G9-1,F10-1) -> 0 | H10: =MAX(G9+IF($A10=H$4,1,-1),H9-1,G10-1) -> 0 | I10: =MAX(H9+IF($A10=I$4,1,-1),I9-1,H10-1) -> -1
A11: challenges | B11: -6 | C11: =MAX(B10+IF($A11=C$4,1,-1),C10-1,B11-1) -> -6 | D11: =MAX(C10+IF($A11=D$4,1,-1),D10-1,C11-1) -> -5 | E11: =MAX(D10+IF($A11=E$4,1,-1),E10-1,D11-1) -> -3 | F11: =MAX(E10+IF($A11=F$4,1,-1),F10-1,E11-1) -> -1 | G11: =MAX(F10+IF($A11=G$4,1,-1),G10-1,F11-1) -> -1 | H11: =MAX(G10+IF($A11=H$4,1,-1),H10-1,G11-1) -> -1 | I11: =MAX(H10+IF($A11=I$4,1,-1),I10-1,H11-1) -> -1
A12: higher | B12: -7 | C12: =MAX(B11+IF($A12=C$4,1,-1),C11-1,B12-1) -> -7 | D12: =MAX(C11+IF($A12=D$4,1,-1),D11-1,C12-1) -> -6 | E12: =MAX(D11+IF($A12=E$4,1,-1),E11-1,D12-1) -> -4 | F12: =MAX(E11+IF($A12=F$4,1,-1),F11-1,E12-1) -> -2 | G12: =MAX(F11+IF($A12=G$4,1,-1),G11-1,F12-1) -> -2 | H12: =MAX(G11+IF($A12=H$4,1,-1),H11-1,G12-1) -> -2 | I12: =MAX(H11+IF($A12=I$4,1,-1),I11-1,H12-1) -> -2
A14: Puntaje F[7][7] | B14: =I12 -> -2 | C14: Programa Java | D14: -2
A16: Alineamiento (traceback desde F[7][7], prefiere diagonal, luego arriba, luego izquierda)
A17: Fila A | B17: - | C17: generative | D17: artificial | E17: intelligence | F17: provides | G17: opportunities | H17: challenges | I17: higher
A18: Fila B | B18: emergence | C18: generative | D18: artificial | E18: intelligence | F18: - | G18: ai | H18: chatgpt | I18: sparked
A19: ¿Coincide? | B19: =IF(AND(B17<>"-",B17=B18),1,0) -> 0 | C19: =IF(AND(C17<>"-",C17=C18),1,0) -> 1 | D19: =IF(AND(D17<>"-",D17=D18),1,0) -> 1 | E19: =IF(AND(E17<>"-",E17=E18),1,0) -> 1 | F19: =IF(AND(F17<>"-",F17=F18),1,0) -> 0 | G19: =IF(AND(G17<>"-",G17=G18),1,0) -> 0 | H19: =IF(AND(H17<>"-",H17=H18),1,0) -> 0 | I19: =IF(AND(I17<>"-",I17=I18),1,0) -> 0
A20: Coincidencias | B20: =SUM(B19:I19) -> 3
A21: Longitud | B21: =COUNTA(B17:I17) -> 8
A22: Similitud = coincidencias / longitud | B22: =B20/B21 -> 0.375 | C22: Programa Java | D22: 0.375
A24: Abstracts completos (hoja 1.2b): puntaje F[114][93] | D24: ='1.2b NW completo'!B2 -> -100
A25: Programa Java: puntaje −100, 8 coincidencias, longitud 116, similitud 0,0690

Sheet 1.1b Levenshtein completo
A1: Levenshtein con los abstracts completos (114 × 93 términos) · resultado:
A2: Celda final | B2: =CQ119 -> 108 | C2: Programa Java: | D2: 108
A4: A \ B | B4: - | C4: emergence | D4: generative | E4: artificial | F4: intelligence | G4: ai | H4: chatgpt | I4: sparked | J4: significant | K4: assessment | L4: concerns | M4: tertiary | N4: education | O4: assessment | P4: concerns | Q4: largely | R4: revolved | S4: around | T4: academic | U4: integrity | V4: issues | W4: students | X4: plagiarism | Y4: cheating | Z4: nonetheless | AA4: critical | AB4: consider | AC4: generative | AD4: ai | AE4: models | AF4: trained | AG4: information | AH4: retrieved | AI4: internet | AJ4: produce | AK4: biased | AL4: discriminatory | AM4: outputs | AN4: hallucination | AO4: issues | AP4: large | AQ4: language | AR4: models | AS4: generative | AT4: ai | AU4: acts | AV4: provide | AW4: made | AX4: untruthful | AY4: outputs | AZ4: article | BA4: considers | BB4: affordances | BC4: challenges | BD4: generative | BE4: ai | BF4: specific | BG4: assessments | BH4: tertiary | BI4: education | BJ4: illustrates | BK4: considerations | BL4: assessment | BM4: redesign | BN4: existence | BO4: generative | BP4: ai | BQ4: proposes | BR4: avoid | BS4: adopt | BT4: aaa | BU4: principle | BV4: rethink | BW4: redesign | BX4: assessments | BY4: argues | BZ4: generative | CA4: ai | CB4: tools | CC4: emerge | CD4: exponentially | CE4: hence | CF4: engaging | CG4: arms | CH4: race | CI4: generative | CJ4: ai | CK4: policing | CL4: use | CM4: technologies | CN4: address | CO4: fundamental | CP4: issues | CQ4: assessments
A5: - | B5: 0 | C5: 1 | D5: 2 | E5: 3 | F5: 4 | G5: 5 | H5: 6 | I5: 7 | J5: 8 | K5: 9 | L5: 10 | M5: 11 | N5: 12 | O5: 13 | P5: 14 | Q5: 15 | R5: 16 | S5: 17 | T5: 18 | U5: 19 | V5: 20 | W5: 21 | X5: 22 | Y5: 23 | Z5: 24 | AA5: 25 | AB5: 26 | AC5: 27 | AD5: 28 | AE5: 29 | AF5: 30 | AG5: 31 | AH5: 32 | AI5: 33 | AJ5: 34 | AK5: 35 | AL5: 36 | AM5: 37 | AN5: 38 | AO5: 39 | AP5: 40 | AQ5: 41 | AR5: 42 | AS5: 43 | AT5: 44 | AU5: 45 | AV5: 46 | AW5: 47 | AX5: 48 | AY5: 49 | AZ5: 50 | BA5: 51 | BB5: 52 | BC5: 53 | BD5: 54 | BE5: 55 | BF5: 56 | BG5: 57 | BH5: 58 | BI5: 59 | BJ5: 60 | BK5: 61 | BL5: 62 | BM5: 63 | BN5: 64 | BO5: 65 | BP5: 66 | BQ5: 67 | BR5: 68 | BS5: 69 | BT5: 70 | BU5: 71 | BV5: 72 | BW5: 73 | BX5: 74 | BY5: 75 | BZ5: 76 | CA5: 77 | CB5: 78 | CC5: 79 | CD5: 80 | CE5: 81 | CF5: 82 | CG5: 83 | CH5: 84 | CI5: 85 | CJ5: 86 | CK5: 87 | CL5: 88 | CM5: 89 | CN5: 90 | CO5: 91 | CP5: 92 | CQ5: 93
A6: generative | B6: 1 | C6: =MIN(C5+1,B6+1,B5+IF($A6=C$4,0,1)) -> 1 | D6: =MIN(D5+1,C6+1,C5+IF($A6=D$4,0,1)) -> 1 | E6: =MIN(E5+1,D6+1,D5+IF($A6=E$4,0,1)) -> 2 | F6: =MIN(F5+1,E6+1,E5+IF($A6=F$4,0,1)) -> 3 | G6: =MIN(G5+1,F6+1,F5+IF($A6=G$4,0,1)) -> 4 | H6: =MIN(H5+1,G6+1,G5+IF($A6=H$4,0,1)) -> 5 | I6: =MIN(I5+1,H6+1,H5+IF($A6=I$4,0,1)) -> 6 | J6: =MIN(J5+1,I6+1,I5+IF($A6=J$4,0,1)) -> 7 | ... CQ6: =MIN(CQ5+1,CP6+1,CP5+IF($A6=CQ$4,0,1)) -> 92
A7: artificial | B7: 2 | C7: =MIN(C6+1,B7+1,B6+IF($A7=C$4,0,1)) -> 2 | D7: =MIN(D6+1,C7+1,C6+IF($A7=D$4,0,1)) -> 2 | E7: =MIN(E6+1,D7+1,D6+IF($A7=E$4,0,1)) -> 1 | F7: =MIN(F6+1,E7+1,E6+IF($A7=F$4,0,1)) -> 2 | G7: =MIN(G6+1,F7+1,F6+IF($A7=G$4,0,1)) -> 3 | H7: =MIN(H6+1,G7+1,G6+IF($A7=H$4,0,1)) -> 4 | I7: =MIN(I6+1,H7+1,H6+IF($A7=I$4,0,1)) -> 5 | J7: =MIN(J6+1,I7+1,I6+IF($A7=J$4,0,1)) -> 6 | ... CQ7: =MIN(CQ6+1,CP7+1,CP6+IF($A7=CQ$4,0,1)) -> 91
A8: intelligence | B8: 3 | C8: =MIN(C7+1,B8+1,B7+IF($A8=C$4,0,1)) -> 3 | D8: =MIN(D7+1,C8+1,C7+IF($A8=D$4,0,1)) -> 3 | E8: =MIN(E7+1,D8+1,D7+IF($A8=E$4,0,1)) -> 2 | F8: =MIN(F7+1,E8+1,E7+IF($A8=F$4,0,1)) -> 1 | G8: =MIN(G7+1,F8+1,F7+IF($A8=G$4,0,1)) -> 2 | H8: =MIN(H7+1,G8+1,G7+IF($A8=H$4,0,1)) -> 3 | I8: =MIN(I7+1,H8+1,H7+IF($A8=I$4,0,1)) -> 4 | J8: =MIN(J7+1,I8+1,I7+IF($A8=J$4,0,1)) -> 5 | ... CQ8: =MIN(CQ7+1,CP8+1,CP7+IF($A8=CQ$4,0,1)) -> 90
A9: provides | B9: 4 | C9: =MIN(C8+1,B9+1,B8+IF($A9=C$4,0,1)) -> 4 | D9: =MIN(D8+1,C9+1,C8+IF($A9=D$4,0,1)) -> 4 | E9: =MIN(E8+1,D9+1,D8+IF($A9=E$4,0,1)) -> 3 | F9: =MIN(F8+1,E9+1,E8+IF($A9=F$4,0,1)) -> 2 | G9: =MIN(G8+1,F9+1,F8+IF($A9=G$4,0,1)) -> 2 | H9: =MIN(H8+1,G9+1,G8+IF($A9=H$4,0,1)) -> 3 | I9: =MIN(I8+1,H9+1,H8+IF($A9=I$4,0,1)) -> 4 | J9: =MIN(J8+1,I9+1,I8+IF($A9=J$4,0,1)) -> 5 | ... CQ9: =MIN(CQ8+1,CP9+1,CP8+IF($A9=CQ$4,0,1)) -> 90
A10: opportunities | B10: 5 | C10: =MIN(C9+1,B10+1,B9+IF($A10=C$4,0,1)) -> 5 | D10: =MIN(D9+1,C10+1,C9+IF($A10=D$4,0,1)) -> 5 | E10: =MIN(E9+1,D10+1,D9+IF($A10=E$4,0,1)) -> 4 | F10: =MIN(F9+1,E10+1,E9+IF($A10=F$4,0,1)) -> 3 | G10: =MIN(G9+1,F10+1,F9+IF($A10=G$4,0,1)) -> 3 | H10: =MIN(H9+1,G10+1,G9+IF($A10=H$4,0,1)) -> 3 | I10: =MIN(I9+1,H10+1,H9+IF($A10=I$4,0,1)) -> 4 | J10: =MIN(J9+1,I10+1,I9+IF($A10=J$4,0,1)) -> 5 | ... CQ10: =MIN(CQ9+1,CP10+1,CP9+IF($A10=CQ$4,0,1)) -> 90
A11: challenges | B11: 6 | C11: =MIN(C10+1,B11+1,B10+IF($A11=C$4,0,1)) -> 6 | D11: =MIN(D10+1,C11+1,C10+IF($A11=D$4,0,1)) -> 6 | E11: =MIN(E10+1,D11+1,D10+IF($A11=E$4,0,1)) -> 5 | F11: =MIN(F10+1,E11+1,E10+IF($A11=F$4,0,1)) -> 4 | G11: =MIN(G10+1,F11+1,F10+IF($A11=G$4,0,1)) -> 4 | H11: =MIN(H10+1,G11+1,G10+IF($A11=H$4,0,1)) -> 4 | I11: =MIN(I10+1,H11+1,H10+IF($A11=I$4,0,1)) -> 4 | J11: =MIN(J10+1,I11+1,I10+IF($A11=J$4,0,1)) -> 5 | ... CQ11: =MIN(CQ10+1,CP11+1,CP10+IF($A11=CQ$4,0,1)) -> 89
A12: higher | B12: 7 | C12: =MIN(C11+1,B12+1,B11+IF($A12=C$4,0,1)) -> 7 | D12: =MIN(D11+1,C12+1,C11+IF($A12=D$4,0,1)) -> 7 | E12: =MIN(E11+1,D12+1,D11+IF($A12=E$4,0,1)) -> 6 | F12: =MIN(F11+1,E12+1,E11+IF($A12=F$4,0,1)) -> 5 | G12: =MIN(G11+1,F12+1,F11+IF($A12=G$4,0,1)) -> 5 | H12: =MIN(H11+1,G12+1,G11+IF($A12=H$4,0,1)) -> 5 | I12: =MIN(I11+1,H12+1,H11+IF($A12=I$4,0,1)) -> 5 | J12: =MIN(J11+1,I12+1,I11+IF($A12=J$4,0,1)) -> 5 | ... CQ12: =MIN(CQ11+1,CP12+1,CP11+IF($A12=CQ$4,0,1)) -> 89
A13: education | B13: 8 | C13: =MIN(C12+1,B13+1,B12+IF($A13=C$4,0,1)) -> 8 | D13: =MIN(D12+1,C13+1,C12+IF($A13=D$4,0,1)) -> 8 | E13: =MIN(E12+1,D13+1,D12+IF($A13=E$4,0,1)) -> 7 | F13: =MIN(F12+1,E13+1,E12+IF($A13=F$4,0,1)) -> 6 | G13: =MIN(G12+1,F13+1,F12+IF($A13=G$4,0,1)) -> 6 | H13: =MIN(H12+1,G13+1,G12+IF($A13=H$4,0,1)) -> 6 | I13: =MIN(I12+1,H13+1,H12+IF($A13=I$4,0,1)) -> 6 | J13: =MIN(J12+1,I13+1,I12+IF($A13=J$4,0,1)) -> 6 | ... CQ13: =MIN(CQ12+1,CP13+1,CP12+IF($A13=CQ$4,0,1)) -> 88
A14: existing | B14: 9 | C14: =MIN(C13+1,B14+1,B13+IF($A14=C$4,0,1)) -> 9 | D14: =MIN(D13+1,C14+1,C13+IF($A14=D$4,0,1)) -> 9 | E14: =MIN(E13+1,D14+1,D13+IF($A14=E$4,0,1)) -> 8 | F14: =MIN(F13+1,E14+1,E13+IF($A14=F$4,0,1)) -> 7 | G14: =MIN(G13+1,F14+1,F13+IF($A14=G$4,0,1)) -> 7 | H14: =MIN(H13+1,G14+1,G13+IF($A14=H$4,0,1)) -> 7 | I14: =MIN(I13+1,H14+1,H13+IF($A14=I$4,0,1)) -> 7 | J14: =MIN(J13+1,I14+1,I13+IF($A14=J$4,0,1)) -> 7 | ... CQ14: =MIN(CQ13+1,CP14+1,CP13+IF($A14=CQ$4,0,1)) -> 88
A15: literature | B15: 10 | C15: =MIN(C14+1,B15+1,B14+IF($A15=C$4,0,1)) -> 10 | D15: =MIN(D14+1,C15+1,C14+IF($A15=D$4,0,1)) -> 10 | E15: =MIN(E14+1,D15+1,D14+IF($A15=E$4,0,1)) -> 9 | F15: =MIN(F14+1,E15+1,E14+IF($A15=F$4,0,1)) -> 8 | G15: =MIN(G14+1,F15+1,F14+IF($A15=G$4,0,1)) -> 8 | H15: =MIN(H14+1,G15+1,G14+IF($A15=H$4,0,1)) -> 8 | I15: =MIN(I14+1,H15+1,H14+IF($A15=I$4,0,1)) -> 8 | J15: =MIN(J14+1,I15+1,I14+IF($A15=J$4,0,1)) -> 8 | ... CQ15: =MIN(CQ14+1,CP15+1,CP14+IF($A15=CQ$4,0,1)) -> 88
A16: properly | B16: 11 | C16: =MIN(C15+1,B16+1,B15+IF($A16=C$4,0,1)) -> 11 | D16: =MIN(D15+1,C16+1,C15+IF($A16=D$4,0,1)) -> 11 | E16: =MIN(E15+1,D16+1,D15+IF($A16=E$4,0,1)) -> 10 | F16: =MIN(F15+1,E16+1,E15+IF($A16=F$4,0,1)) -> 9 | G16: =MIN(G15+1,F16+1,F15+IF($A16=G$4,0,1)) -> 9 | H16: =MIN(H15+1,G16+1,G15+IF($A16=H$4,0,1)) -> 9 | I16: =MIN(I15+1,H16+1,H15+IF($A16=I$4,0,1)) -> 9 | J16: =MIN(J15+1,I16+1,I15+IF($A16=J$4,0,1)) -> 9 | ... CQ16: =MIN(CQ15+1,CP16+1,CP15+IF($A16=CQ$4,0,1)) -> 88
A17: investigated | B17: 12 | C17: =MIN(C16+1,B17+1,B16+IF($A17=C$4,0,1)) -> 12 | D17: =MIN(D16+1,C17+1,C16+IF($A17=D$4,0,1)) -> 12 | E17: =MIN(E16+1,D17+1,D16+IF($A17=E$4,0,1)) -> 11 | F17: =MIN(F16+1,E17+1,E16+IF($A17=F$4,0,1)) -> 10 | G17: =MIN(G16+1,F17+1,F16+IF($A17=G$4,0,1)) -> 10 | H17: =MIN(H16+1,G17+1,G16+IF($A17=H$4,0,1)) -> 10 | I17: =MIN(I16+1,H17+1,H16+IF($A17=I$4,0,1)) -> 10 | J17: =MIN(J16+1,I17+1,I16+IF($A17=J$4,0,1)) -> 10 | ... CQ17: =MIN(CQ16+1,CP17+1,CP16+IF($A17=CQ$4,0,1)) -> 88
... A119: teaching | B119: 114 | C119: =MIN(C118+1,B119+1,B118+IF($A119=C$4,0,1)) -> 114 | D119: =MIN(D118+1,C119+1,C118+IF($A119=D$4,0,1)) -> 113 | E119: =MIN(E118+1,D119+1,D118+IF($A119=E$4,0,1)) -> 112 | F119: =MIN(F118+1,E119+1,E118+IF($A119=F$4,0,1)) -> 111 | G119: =MIN(G118+1,F119+1,F118+IF($A119=G$4,0,1)) -> 110 | H119: =MIN(H118+1,G119+1,G118+IF($A119=H$4,0,1)) -> 110 | I119: =MIN(I118+1,H119+1,H118+IF($A119=I$4,0,1)) -> 110 | J119: =MIN(J118+1,I119+1,I118+IF($A119=J$4,0,1)) -> 110 | ... CQ119: =MIN(CQ118+1,CP119+1,CP118+IF($A119=CQ$4,0,1)) -> 108

Sheet 1.2b NW completo
A1: Needleman-Wunsch con los abstracts completos (114 × 93 términos) · resultado:
A2: Celda final | B2: =CQ119 -> -100 | C2: Programa Java: | D2: -100
A4: A \ B | B4: - | C4: emergence | D4: generative | E4: artificial | F4: intelligence | G4: ai | H4: chatgpt | I4: sparked | J4: significant | K4: assessment | L4: concerns | M4: tertiary | N4: education | O4: assessment | P4: concerns | Q4: largely | R4: revolved | S4: around | T4: academic | U4: integrity | V4: issues | W4: students | X4: plagiarism | Y4: cheating | Z4: nonetheless | AA4: critical | AB4: consider | AC4: generative | AD4: ai | AE4: models | AF4: trained | AG4: information | AH4: retrieved | AI4: internet | AJ4: produce | AK4: biased | AL4: discriminatory | AM4: outputs | AN4: hallucination | AO4: issues | AP4: large | AQ4: language | AR4: models | AS4: generative | AT4: ai | AU4: acts | AV4: provide | AW4: made | AX4: untruthful | AY4: outputs | AZ4: article | BA4: considers | BB4: affordances | BC4: challenges | BD4: generative | BE4: ai | BF4: specific | BG4: assessments | BH4: tertiary | BI4: education | BJ4: illustrates | BK4: considerations | BL4: assessment | BM4: redesign | BN4: existence | BO4: generative | BP4: ai | BQ4: proposes | BR4: avoid | BS4: adopt | BT4: aaa | BU4: principle | BV4: rethink | BW4: redesign | BX4: assessments | BY4: argues | BZ4: generative | CA4: ai | CB4: tools | CC4: emerge | CD4: exponentially | CE4: hence | CF4: engaging | CG4: arms | CH4: race | CI4: generative | CJ4: ai | CK4: policing | CL4: use | CM4: technologies | CN4: address | CO4: fundamental | CP4: issues | CQ4: assessments
A5: - | B5: 0 | C5: -1 | D5: -2 | E5: -3 | F5: -4 | G5: -5 | H5: -6 | I5: -7 | J5: -8 | K5: -9 | L5: -10 | M5: -11 | N5: -12 | O5: -13 | P5: -14 | Q5: -15 | R5: -16 | S5: -17 | T5: -18 | U5: -19 | V5: -20 | W5: -21 | X5: -22 | Y5: -23 | Z5: -24 | AA5: -25 | AB5: -26 | AC5: -27 | AD5: -28 | AE5: -29 | AF5: -30 | AG5: -31 | AH5: -32 | AI5: -33 | AJ5: -34 | AK5: -35 | AL5: -36 | AM5: -37 | AN5: -38 | AO5: -39 | AP5: -40 | AQ5: -41 | AR5: -42 | AS5: -43 | AT5: -44 | AU5: -45 | AV5: -46 | AW5: -47 | AX5: -48 | AY5: -49 | AZ5: -50 | BA5: -51 | BB5: -52 | BC5: -53 | BD5: -54 | BE5: -55 | BF5: -56 | BG5: -57 | BH5: -58 | BI5: -59 | BJ5: -60 | BK5: -61 | BL5: -62 | BM5: -63 | BN5: -64 | BO5: -65 | BP5: -66 | BQ5: -67 | BR5: -68 | BS5: -69 | BT5: -70 | BU5: -71 | BV5: -72 | BW5: -73 | BX5: -74 | BY5: -75 | BZ5: -76 | CA5: -77 | CB5: -78 | CC5: -79 | CD5: -80 | CE5: -81 | CF5: -82 | CG5: -83 | CH5: -84 | CI5: -85 | CJ5: -86 | CK5: -87 | CL5: -88 | CM5: -89 | CN5: -90 | CO5: -91 | CP5: -92 | CQ5: -93
A6: generative | B6: -1 | C6: =MAX(B5+IF($A6=C$4,1,-1),C5-1,B6-1) -> -1 | D6: =MAX(C5+IF($A6=D$4,1,-1),D5-1,C6-1) -> 0 | E6: =MAX(D5+IF($A6=E$4,1,-1),E5-1,D6-1) -> -1 | F6: =MAX(E5+IF($A6=F$4,1,-1),F5-1,E6-1) -> -2 | G6: =MAX(F5+IF($A6=G$4,1,-1),G5-1,F6-1) -> -3 | H6: =MAX(G5+IF($A6=H$4,1,-1),H5-1,G6-1) -> -4 | I6: =MAX(H5+IF($A6=I$4,1,-1),I5-1,H6-1) -> -5 | J6: =MAX(I5+IF($A6=J$4,1,-1),J5-1,I6-1) -> -6 | ... CQ6: =MAX(CP5+IF($A6=CQ$4,1,-1),CQ5-1,CP6-1) -> -91
A7: artificial | B7: -2 | C7: =MAX(B6+IF($A7=C$4,1,-1),C6-1,B7-1) -> -2 | D7: =MAX(C6+IF($A7=D$4,1,-1),D6-1,C7-1) -> -1 | E7: =MAX(D6+IF($A7=E$4,1,-1),E6-1,D7-1) -> 1 | F7: =MAX(E6+IF($A7=F$4,1,-1),F6-1,E7-1) -> 0 | G7: =MAX(F6+IF($A7=G$4,1,-1),G6-1,F7-1) -> -1 | H7: =MAX(G6+IF($A7=H$4,1,-1),H6-1,G7-1) -> -2 | I7: =MAX(H6+IF($A7=I$4,1,-1),I6-1,H7-1) -> -3 | J7: =MAX(I6+IF($A7=J$4,1,-1),J6-1,I7-1) -> -4 | ... CQ7: =MAX(CP6+IF($A7=CQ$4,1,-1),CQ6-1,CP7-1) -> -89
A8: intelligence | B8: -3 | C8: =MAX(B7+IF($A8=C$4,1,-1),C7-1,B8-1) -> -3 | D8: =MAX(C7+IF($A8=D$4,1,-1),D7-1,C8-1) -> -2 | E8: =MAX(D7+IF($A8=E$4,1,-1),E7-1,D8-1) -> 0 | F8: =MAX(E7+IF($A8=F$4,1,-1),F7-1,E8-1) -> 2 | G8: =MAX(F7+IF($A8=G$4,1,-1),G7-1,F8-1) -> 1 | H8: =MAX(G7+IF($A8=H$4,1,-1),H7-1,G8-1) -> 0 | I8: =MAX(H7+IF($A8=I$4,1,-1),I7-1,H8-1) -> -1 | J8: =MAX(I7+IF($A8=J$4,1,-1),J7-1,I8-1) -> -2 | ... CQ8: =MAX(CP7+IF($A8=CQ$4,1,-1),CQ7-1,CP8-1) -> -87
A9: provides | B9: -4 | C9: =MAX(B8+IF($A9=C$4,1,-1),C8-1,B9-1) -> -4 | D9: =MAX(C8+IF($A9=D$4,1,-1),D8-1,C9-1) -> -3 | E9: =MAX(D8+IF($A9=E$4,1,-1),E8-1,D9-1) -> -1 | F9: =MAX(E8+IF($A9=F$4,1,-1),F8-1,E9-1) -> 1 | G9: =MAX(F8+IF($A9=G$4,1,-1),G8-1,F9-1) -> 1 | H9: =MAX(G8+IF($A9=H$4,1,-1),H8-1,G9-1) -> 0 | I9: =MAX(H8+IF($A9=I$4,1,-1),I8-1,H9-1) -> -1 | J9: =MAX(I8+IF($A9=J$4,1,-1),J8-1,I9-1) -> -2 | ... CQ9: =MAX(CP8+IF($A9=CQ$4,1,-1),CQ8-1,CP9-1) -> -87
A10: opportunities | B10: -5 | C10: =MAX(B9+IF($A10=C$4,1,-1),C9-1,B10-1) -> -5 | D10: =MAX(C9+IF($A10=D$4,1,-1),D9-1,C10-1) -> -4 | E10: =MAX(D9+IF($A10=E$4,1,-1),E9-1,D10-1) -> -2 | F10: =MAX(E9+IF($A10=F$4,1,-1),F9-1,E10-1) -> 0 | G10: =MAX(F9+IF($A10=G$4,1,-1),G9-1,F10-1) -> 0 | H10: =MAX(G9+IF($A10=H$4,1,-1),H9-1,G10-1) -> 0 | I10: =MAX(H9+IF($A10=I$4,1,-1),I9-1,H10-1) -> -1 | J10: =MAX(I9+IF($A10=J$4,1,-1),J9-1,I10-1) -> -2 | ... CQ10: =MAX(CP9+IF($A10=CQ$4,1,-1),CQ9-1,CP10-1) -> -87
A11: challenges | B11: -6 | C11: =MAX(B10+IF($A11=C$4,1,-1),C10-1,B11-1) -> -6 | D11: =MAX(C10+IF($A11=D$4,1,-1),D10-1,C11-1) -> -5 | E11: =MAX(D10+IF($A11=E$4,1,-1),E10-1,D11-1) -> -3 | F11: =MAX(E10+IF($A11=F$4,1,-1),F10-1,E11-1) -> -1 | G11: =MAX(F10+IF($A11=G$4,1,-1),G10-1,F11-1) -> -1 | H11: =MAX(G10+IF($A11=H$4,1,-1),H10-1,G11-1) -> -1 | I11: =MAX(H10+IF($A11=I$4,1,-1),I10-1,H11-1) -> -1 | J11: =MAX(I10+IF($A11=J$4,1,-1),J10-1,I11-1) -> -2 | ... CQ11: =MAX(CP10+IF($A11=CQ$4,1,-1),CQ10-1,CP11-1) -> -85
A12: higher | B12: -7 | C12: =MAX(B11+IF($A12=C$4,1,-1),C11-1,B12-1) -> -7 | D12: =MAX(C11+IF($A12=D$4,1,-1),D11-1,C12-1) -> -6 | E12: =MAX(D11+IF($A12=E$4,1,-1),E11-1,D12-1) -> -4 | F12: =MAX(E11+IF($A12=F$4,1,-1),F11-1,E12-1) -> -2 | G12: =MAX(F11+IF($A12=G$4,1,-1),G11-1,F12-1) -> -2 | H12: =MAX(G11+IF($A12=H$4,1,-1),H11-1,G12-1) -> -2 | I12: =MAX(H11+IF($A12=I$4,1,-1),I11-1,H12-1) -> -2 | J12: =MAX(I11+IF($A12=J$4,1,-1),J11-1,I12-1) -> -2 | ... CQ12: =MAX(CP11+IF($A12=CQ$4,1,-1),CQ11-1,CP12-1) -> -85
A13: education | B13: -8 | C13: =MAX(B12+IF($A13=C$4,1,-1),C12-1,B13-1) -> -8 | D13: =MAX(C12+IF($A13=D$4,1,-1),D12-1,C13-1) -> -7 | E13: =MAX(D12+IF($A13=E$4,1,-1),E12-1,D13-1) -> -5 | F13: =MAX(E12+IF($A13=F$4,1,-1),F12-1,E13-1) -> -3 | G13: =MAX(F12+IF($A13=G$4,1,-1),G12-1,F13-1) -> -3 | H13: =MAX(G12+IF($A13=H$4,1,-1),H12-1,G13-1) -> -3 | I13: =MAX(H12+IF($A13=I$4,1,-1),I12-1,H13-1) -> -3 | J13: =MAX(I12+IF($A13=J$4,1,-1),J12-1,I13-1) -> -3 | ... CQ13: =MAX(CP12+IF($A13=CQ$4,1,-1),CQ12-1,CP13-1) -> -83
A14: existing | B14: -9 | C14: =MAX(B13+IF($A14=C$4,1,-1),C13-1,B14-1) -> -9 | D14: =MAX(C13+IF($A14=D$4,1,-1),D13-1,C14-1) -> -8 | E14: =MAX(D13+IF($A14=E$4,1,-1),E13-1,D14-1) -> -6 | F14: =MAX(E13+IF($A14=F$4,1,-1),F13-1,E14-1) -> -4 | G14: =MAX(F13+IF($A14=G$4,1,-1),G13-1,F14-1) -> -4 | H14: =MAX(G13+IF($A14=H$4,1,-1),H13-1,G14-1) -> -4 | I14: =MAX(H13+IF($A14=I$4,1,-1),I13-1,H14-1) -> -4 | J14: =MAX(I13+IF($A14=J$4,1,-1),J13-1,I14-1) -> -4 | ... CQ14: =MAX(CP13+IF($A14=CQ$4,1,-1),CQ13-1,CP14-1) -> -83
A15: literature | B15: -10 | C15: =MAX(B14+IF($A15=C$4,1,-1),C14-1,B15-1) -> -10 | D15: =MAX(C14+IF($A15=D$4,1,-1),D14-1,C15-1) -> -9 | E15: =MAX(D14+IF($A15=E$4,1,-1),E14-1,D15-1) -> -7 | F15: =MAX(E14+IF($A15=F$4,1,-1),F14-1,E15-1) -> -5 | G15: =MAX(F14+IF($A15=G$4,1,-1),G14-1,F15-1) -> -5 | H15: =MAX(G14+IF($A15=H$4,1,-1),H14-1,G15-1) -> -5 | I15: =MAX(H14+IF($A15=I$4,1,-1),I14-1,H15-1) -> -5 | J15: =MAX(I14+IF($A15=J$4,1,-1),J14-1,I15-1) -> -5 | ... CQ15: =MAX(CP14+IF($A15=CQ$4,1,-1),CQ14-1,CP15-1) -> -83
A16: properly | B16: -11 | C16: =MAX(B15+IF($A16=C$4,1,-1),C15-1,B16-1) -> -11 | D16: =MAX(C15+IF($A16=D$4,1,-1),D15-1,C16-1) -> -10 | E16: =MAX(D15+IF($A16=E$4,1,-1),E15-1,D16-1) -> -8 | F16: =MAX(E15+IF($A16=F$4,1,-1),F15-1,E16-1) -> -6 | G16: =MAX(F15+IF($A16=G$4,1,-1),G15-1,F16-1) -> -6 | H16: =MAX(G15+IF($A16=H$4,1,-1),H15-1,G16-1) -> -6 | I16: =MAX(H15+IF($A16=I$4,1,-1),I15-1,H16-1) -> -6 | J16: =MAX(I15+IF($A16=J$4,1,-1),J15-1,I16-1) -> -6 | ... CQ16: =MAX(CP15+IF($A16=CQ$4,1,-1),CQ15-1,CP16-1) -> -83
A17: investigated | B17: -12 | C17: =MAX(B16+IF($A17=C$4,1,-1),C16-1,B17-1) -> -12 | D17: =MAX(C16+IF($A17=D$4,1,-1),D16-1,C17-1) -> -11 | E17: =MAX(D16+IF($A17=E$4,1,-1),E16-1,D17-1) -> -9 | F17: =MAX(E16+IF($A17=F$4,1,-1),F16-1,E17-1) -> -7 | G17: =MAX(F16+IF($A17=G$4,1,-1),G16-1,F17-1) -> -7 | H17: =MAX(G16+IF($A17=H$4,1,-1),H16-1,G17-1) -> -7 | I17: =MAX(H16+IF($A17=I$4,1,-1),I16-1,H17-1) -> -7 | J17: =MAX(I16+IF($A17=J$4,1,-1),J16-1,I17-1) -> -7 | ... CQ17: =MAX(CP16+IF($A17=CQ$4,1,-1),CQ16-1,CP17-1) -> -83
... A119: teaching | B119: -114 | C119: =MAX(B118+IF($A119=C$4,1,-1),C118-1,B119-1) -> -114 | D119: =MAX(C118+IF($A119=D$4,1,-1),D118-1,C119-1) -> -112 | E119: =MAX(D118+IF($A119=E$4,1,-1),E118-1,D119-1) -> -110 | F119: =MAX(E118+IF($A119=F$4,1,-1),F118-1,E119-1) -> -108 | G119: =MAX(F118+IF($A119=G$4,1,-1),G118-1,F119-1) -> -106 | H119: =MAX(G118+IF($A119=H$4,1,-1),H118-1,G119-1) -> -106 | I119: =MAX(H118+IF($A119=I$4,1,-1),I118-1,H119-1) -> -106 | J119: =MAX(I118+IF($A119=J$4,1,-1),J118-1,I119-1) -> -106 | ... CQ119: =MAX(CP118+IF($A119=CQ$4,1,-1),CQ118-1,CP119-1) -> -100

Sheet 1.3 TF-IDF coseno
A1: Coseno con TF-IDF entre los abstracts 11 y 16
A2: tf = veces que el término aparece en el abstract (COUNTIF sobre las columnas M y N); idf = log10(N / df); w = tf · idf; cos = Σ wA·wB / (|A| |B|). Código: TfIdf.java 48-71, Vectores.java 32.
A4: N (abstracts del corpus) | B4: 20 | L4: Producto punto A·B | P4: =SUM(H10:H147) -> 10.976321 | Q4: Programa Java | R4: 10.9763
A5: Términos de A (art. 11) | B5: =COUNTA(M10:M123) -> 114 | L5: |A| | P5: =SQRT(SUM(I10:I147)) -> 9.801942 | Q5: 9.8019
A6: Términos de B (art. 16) | B6: =COUNTA(N10:N102) -> 93 | L6: |B| | P6: =SQRT(SUM(J10:J147)) -> 11.183662 | Q6: 11.1837
L7: cos θ = A·B / (|A| |B|) | P7: =P4/(P5*P6) -> 0.10012917 | Q7: 0.1001
L8: θ (grados) | P8: =DEGREES(ACOS(P7)) -> 84.253391 | Q8: 84.25
A9: Término | B9: tf A | C9: tf B | D9: df | E9: idf | F9: w A | G9: w B | H9: wA · wB | I9: wA² | J9: wB² | M9: Secuencia A | N9: Secuencia B
A10: generative | B10: =COUNTIF($M$10:$M$123,A10) -> 2 | C10: =COUNTIF($N$10:$N$102,A10) -> 7 | D10: 5 | E10: =LOG10($B$4/D10) -> 0.60205999 | F10: =B10*E10 -> 1.20412 | G10: =C10*E10 -> 4.2144199 | H10: =F10*G10 -> 5.0746673 | I10: =F10^2 -> 1.4499049 | J10: =G10^2 -> 17.761335 | M10: generative | N10: emergence
A11: artificial | B11: =COUNTIF($M$10:$M$123,A11) -> 2 | C11: =COUNTIF($N$10:$N$102,A11) -> 1 | D11: 20 | E11: =LOG10($B$4/D11) -> 0 | F11: =B11*E11 -> 0 | G11: =C11*E11 -> 0 | H11: =F11*G11 -> 0 | I11: =F11^2 -> 0 | J11: =G11^2 -> 0 | M11: artificial | N11: generative
A12: intelligence | B12: =COUNTIF($M$10:$M$123,A12) -> 2 | C12: =COUNTIF($N$10:$N$102,A12) -> 1 | D12: 20 | E12: =LOG10($B$4/D12) -> 0 | F12: =B12*E12 -> 0 | G12: =C12*E12 -> 0 | H12: =F12*G12 -> 0 | I12: =F12^2 -> 0 | J12: =G12^2 -> 0 | M12: intelligence | N12: artificial
A13: provides | B13: =COUNTIF($M$10:$M$123,A13) -> 1 | C13: =COUNTIF($N$10:$N$102,A13) -> 0 | D13: 4 | E13: =LOG10($B$4/D13) -> 0.69897 | F13: =B13*E13 -> 0.69897 | G13: =C13*E13 -> 0 | H13: =F13*G13 -> 0 | I13: =F13^2 -> 0.48855907 | J13: =G13^2 -> 0 | M13: provides | N13: intelligence
A14: opportunities | B14: =COUNTIF($M$10:$M$123,A14) -> 1 | C14: =COUNTIF($N$10:$N$102,A14) -> 0 | D14: 4 | E14: =LOG10($B$4/D14) -> 0.69897 | F14: =B14*E14 -> 0.69897 | G14: =C14*E14 -> 0 | H14: =F14*G14 -> 0 | I14: =F14^2 -> 0.48855907 | J14: =G14^2 -> 0 | M14: opportunities | N14: ai
A15: challenges | B15: =COUNTIF($M$10:$M$123,A15) -> 1 | C15: =COUNTIF($N$10:$N$102,A15) -> 1 | D15: 6 | E15: =LOG10($B$4/D15) -> 0.52287875 | F15: =B15*E15 -> 0.52287875 | G15: =C15*E15 -> 0.52287875 | H15: =F15*G15 -> 0.27340218 | I15: =F15^2 -> 0.27340218 | J15: =G15^2 -> 0.27340218 | M15: challenges | N15: chatgpt
A16: higher | B16: =COUNTIF($M$10:$M$123,A16) -> 4 | C16: =COUNTIF($N$10:$N$102,A16) -> 0 | D16: 6 | E16: =LOG10($B$4/D16) -> 0.52287875 | F16: =B16*E16 -> 2.091515 | G16: =C16*E16 -> 0 | H16: =F16*G16 -> 0 | I16: =F16^2 -> 4.3744349 | J16: =G16^2 -> 0 | M16: higher | N16: sparked
A17: education | B17: =COUNTIF($M$10:$M$123,A17) -> 4 | C17: =COUNTIF($N$10:$N$102,A17) -> 2 | D17: 18 | E17: =LOG10($B$4/D17) -> 0.045757491 | F17: =B17*E17 -> 0.18302996 | G17: =C17*E17 -> 0.091514981 | H17: =F17*G17 -> 0.016749984 | I17: =F17^2 -> 0.033499967 | J17: =G17^2 -> 0.0083749918 | M17: education | N17: significant
A18: existing | B18: =COUNTIF($M$10:$M$123,A18) -> 1 | C18: =COUNTIF($N$10:$N$102,A18) -> 0 | D18: 2 | E18: =LOG10($B$4/D18) -> 1 | F18: =B18*E18 -> 1 | G18: =C18*E18 -> 0 | H18: =F18*G18 -> 0 | I18: =F18^2 -> 1 | J18: =G18^2 -> 0 | M18: existing | N18: assessment
A19: literature | B19: =COUNTIF($M$10:$M$123,A19) -> 1 | C19: =COUNTIF($N$10:$N$102,A19) -> 0 | D19: 11 | E19: =LOG10($B$4/D19) -> 0.25963731 | F19: =B19*E19 -> 0.25963731 | G19: =C19*E19 -> 0 | H19: =F19*G19 -> 0 | I19: =F19^2 -> 0.067411533 | J19: =G19^2 -> 0 | M19: literature | N19: concerns
A20: properly | B20: =COUNTIF($M$10:$M$123,A20) -> 1 | C20: =COUNTIF($N$10:$N$102,A20) -> 0 | D20: 1 | E20: =LOG10($B$4/D20) -> 1.30103 | F20: =B20*E20 -> 1.30103 | G20: =C20*E20 -> 0 | H20: =F20*G20 -> 0 | I20: =F20^2 -> 1.692679 | J20: =G20^2 -> 0 | M20: properly | N20: tertiary
A21: investigated | B21: =COUNTIF($M$10:$M$123,A21) -> 1 | C21: =COUNTIF($N$10:$N$102,A21) -> 0 | D21: 2 | E21: =LOG10($B$4/D21) -> 1 | F21: =B21*E21 -> 1 | G21: =C21*E21 -> 0 | H21: =F21*G21 -> 0 | I21: =F21^2 -> 1 | J21: =G21^2 -> 0 | M21: investigated | N21: education
... A102: plagiarism | B102: =COUNTIF($M$10:$M$123,A102) -> 0 | C102: =COUNTIF($N$10:$N$102,A102) -> 1 | D102: 2 | E102: =LOG10($B$4/D102) -> 1 | F102: =B102*E102 -> 0 | G102: =C102*E102 -> 1 | H102: =F102*G102 -> 0 | I102: =F102^2 -> 0 | J102: =G102^2 -> 1 | M102: assessment | N102: assessments
A103: cheating | B103: =COUNTIF($M$10:$M$123,A103) -> 0 | C103: =COUNTIF($N$10:$N$102,A103) -> 1 | D103: 1 | E103: =LOG10($B$4/D103) -> 1.30103 | F103: =B103*E103 -> 0 | G103: =C103*E103 -> 1.30103 | H103: =F103*G103 -> 0 | I103: =F103^2 -> 0 | J103: =G103^2 -> 1.692679 | M103: strengthened
A104: nonetheless | B104: =COUNTIF($M$10:$M$123,A104) -> 0 | C104: =COUNTIF($N$10:$N$102,A104) -> 1 | D104: 1 | E104: =LOG10($B$4/D104) -> 1.30103 | F104: =B104*E104 -> 0 | G104: =C104*E104 -> 1.30103 | H104: =F104*G104 -> 0 | I104: =F104^2 -> 0 | J104: =G104^2 -> 1.692679 | M104: iii
A105: critical | B105: =COUNTIF($M$10:$M$123,A105) -> 0 | C105: =COUNTIF($N$10:$N$102,A105) -> 1 | D105: 4 | E105: =LOG10($B$4/D105) -> 0.69897 | F105: =B105*E105 -> 0 | G105: =C105*E105 -> 0.69897 | H105: =F105*G105 -> 0 | I105: =F105^2 -> 0 | J105: =G105^2 -> 0.48855907 | M105: teachers
A106: consider | B106: =COUNTIF($M$10:$M$123,A106) -> 0 | C106: =COUNTIF($N$10:$N$102,A106) -> 1 | D106: 1 | E106: =LOG10($B$4/D106) -> 1.30103 | F106: =B106*E106 -> 0 | G106: =C106*E106 -> 1.30103 | H106: =F106*G106 -> 0 | I106: =F106^2 -> 0 | J106: =G106^2 -> 1.692679 | M106: innovative
A107: models | B107: =COUNTIF($M$10:$M$123,A107) -> 0 | C107: =COUNTIF($N$10:$N$102,A107) -> 2 | D107: 3 | E107: =LOG10($B$4/D107) -> 0.82390874 | F107: =B107*E107 -> 0 | G107: =C107*E107 -> 1.6478175 | H107: =F107*G107 -> 0 | I107: =F107^2 -> 0 | J107: =G107^2 -> 2.7153025 | M107: holistic
A108: trained | B108: =COUNTIF($M$10:$M$123,A108) -> 0 | C108: =COUNTIF($N$10:$N$102,A108) -> 1 | D108: 1 | E108: =LOG10($B$4/D108) -> 1.30103 | F108: =B108*E108 -> 0 | G108: =C108*E108 -> 1.30103 | H108: =F108*G108 -> 0 | I108: =F108^2 -> 0 | J108: =G108^2 -> 1.692679 | M108: teaching
A109: information | B109: =COUNTIF($M$10:$M$123,A109) -> 0 | C109: =COUNTIF($N$10:$N$102,A109) -> 1 | D109: 2 | E109: =LOG10($B$4/D109) -> 1 | F109: =B109*E109 -> 0 | G109: =C109*E109 -> 1 | H109: =F109*G109 -> 0 | I109: =F109^2 -> 0 | J109: =G109^2 -> 1 | M109: reflect
A110: internet | B110: =COUNTIF($M$10:$M$123,A110) -> 0 | C110: =COUNTIF($N$10:$N$102,A110) -> 1 | D110: 1 | E110: =LOG10($B$4/D110) -> 1.30103 | F110: =B110*E110 -> 0 | G110: =C110*E110 -> 1.30103 | H110: =F110*G110 -> 0 | I110: =F110^2 -> 0 | J110: =G110^2 -> 1.692679 | M110: assessment
A111: produce | B111: =COUNTIF($M$10:$M$123,A111) -> 0 | C111: =COUNTIF($N$10:$N$102,A111) -> 1 | D111: 1 | E111: =LOG10($B$4/D111) -> 1.30103 | F111: =B111*E111 -> 0 | G111: =C111*E111 -> 1.30103 | H111: =F111*G111 -> 0 | I111: =F111^2 -> 0 | J111: =G111^2 -> 1.692679 | M111: transformation
A112: biased | B112: =COUNTIF($M$10:$M$123,A112) -> 0 | C112: =COUNTIF($N$10:$N$102,A112) -> 1 | D112: 1 | E112: =LOG10($B$4/D112) -> 1.30103 | F112: =B112*E112 -> 0 | G112: =C112*E112 -> 1.30103 | H112: =F112*G112 -> 0 | I112: =F112^2 -> 0 | J112: =G112^2 -> 1.692679 | M112: educational
A113: discriminatory | B113: =COUNTIF($M$10:$M$123,A113) -> 0 | C113: =COUNTIF($N$10:$N$102,A113) -> 1 | D113: 1 | E113: =LOG10($B$4/D113) -> 1.30103 | F113: =B113*E113 -> 0 | G113: =C113*E113 -> 1.30103 | H113: =F113*G113 -> 0 | I113: =F113^2 -> 0 | J113: =G113^2 -> 1.692679 | M113: institutions
A114: outputs | B114: =COUNTIF($M$10:$M$123,A114) -> 0 | C114: =COUNTIF($N$10:$N$102,A114) -> 2 | D114: 1 | E114: =LOG10($B$4/D114) -> 1.30103 | F114: =B114*E114 -> 0 | G114: =C114*E114 -> 2.60206 | H114: =F114*G114 -> 0 | I114: =F114^2 -> 0 | J114: =G114^2 -> 6.7707162 | M114: recommended
... A123: affordances | B123: =COUNTIF($M$10:$M$123,A123) -> 0 | C123: =COUNTIF($N$10:$N$102,A123) -> 1 | D123: 1 | E123: =LOG10($B$4/D123) -> 1.30103 | F123: =B123*E123 -> 0 | G123: =C123*E123 -> 1.30103 | H123: =F123*G123 -> 0 | I123: =F123^2 -> 0 | J123: =G123^2 -> 1.692679 | M123: teaching
A124: specific | B124: =COUNTIF($M$10:$M$123,A124) -> 0 | C124: =COUNTIF($N$10:$N$102,A124) -> 1 | D124: 2 | E124: =LOG10($B$4/D124) -> 1 | F124: =B124*E124 -> 0 | G124: =C124*E124 -> 1 | H124: =F124*G124 -> 0 | I124: =F124^2 -> 0 | J124: =G124^2 -> 1
A125: assessments | B125: =COUNTIF($M$10:$M$123,A125) -> 0 | C125: =COUNTIF($N$10:$N$102,A125) -> 3 | D125: 3 | E125: =LOG10($B$4/D125) -> 0.82390874 | F125: =B125*E125 -> 0 | G125: =C125*E125 -> 2.4717262 | H125: =F125*G125 -> 0 | I125: =F125^2 -> 0 | J125: =G125^2 -> 6.1094305
A126: illustrates | B126: =COUNTIF($M$10:$M$123,A126) -> 0 | C126: =COUNTIF($N$10:$N$102,A126) -> 1 | D126: 1 | E126: =LOG10($B$4/D126) -> 1.30103 | F126: =B126*E126 -> 0 | G126: =C126*E126 -> 1.30103 | H126: =F126*G126 -> 0 | I126: =F126^2 -> 0 | J126: =G126^2 -> 1.692679
A127: considerations | B127: =COUNTIF($M$10:$M$123,A127) -> 0 | C127: =COUNTIF($N$10:$N$102,A127) -> 1 | D127: 3 | E127: =LOG10($B$4/D127) -> 0.82390874 | F127: =B127*E127 -> 0 | G127: =C127*E127 -> 0.82390874 | H127: =F127*G127 -> 0 | I127: =F127^2 -> 0 | J127: =G127^2 -> 0.67882561
A128: redesign | B128: =COUNTIF($M$10:$M$123,A128) -> 0 | C128: =COUNTIF($N$10:$N$102,A128) -> 2 | D128: 1 | E128: =LOG10($B$4/D128) -> 1.30103 | F128: =B128*E128 -> 0 | G128: =C128*E128 -> 2.60206 | H128: =F128*G128 -> 0 | I128: =F128^2 -> 0 | J128: =G128^2 -> 6.7707162
A129: existence | B129: =COUNTIF($M$10:$M$123,A129) -> 0 | C129: =COUNTIF($N$10:$N$102,A129) -> 1 | D129: 1 | E129: =LOG10($B$4/D129) -> 1.30103 | F129: =B129*E129 -> 0 | G129: =C129*E129 -> 1.30103 | H129: =F129*G129 -> 0 | I129: =F129^2 -> 0 | J129: =G129^2 -> 1.692679
...

Sheet 1.4 Jaccard
A1: Coeficiente de Jaccard entre los conjuntos de términos de 11 y 16
A2: J(A, B) = |A ∩ B| / |A ∪ B|, con |A ∪ B| = |A| + |B| − |A ∩ B|. Los conjuntos ignoran repeticiones y orden. Código: Jaccard.java 41-46.
F4: |A| | G4: =SUM(B10:B147) -> 81 | H4: Programa Java | I4: 81
F5: |B| | G5: =SUM(C10:C147) -> 69 | I5: 69
F6: |A ∩ B| | G6: =SUM(D10:D147) -> 12 | I6: 12
F7: |A ∪ B| = |A| + |B| − |A ∩ B| | G7: =G4+G5-G6 -> 138 | I7: 138
F8: J = |A ∩ B| / |A ∪ B| | G8: =G6/G7 -> 0.086956522 | I8: 0.087
A9: Término de A ∪ B | B9: ∈ A | C9: ∈ B | D9: ∈ A ∩ B
A10: ='1.3 TF-IDF coseno'!A10 -> generative | B10: =IF('1.3 TF-IDF coseno'!B10>0,1,0) -> 1 | C10: =IF('1.3 TF-IDF coseno'!C10>0,1,0) -> 1 | D10: =B10*C10 -> 1
A11: ='1.3 TF-IDF coseno'!A11 -> artificial | B11: =IF('1.3 TF-IDF coseno'!B11>0,1,0) -> 1 | C11: =IF('1.3 TF-IDF coseno'!C11>0,1,0) -> 1 | D11: =B11*C11 -> 1
A12: ='1.3 TF-IDF coseno'!A12 -> intelligence | B12: =IF('1.3 TF-IDF coseno'!B12>0,1,0) -> 1 | C12: =IF('1.3 TF-IDF coseno'!C12>0,1,0) -> 1 | D12: =B12*C12 -> 1
A13: ='1.3 TF-IDF coseno'!A13 -> provides | B13: =IF('1.3 TF-IDF coseno'!B13>0,1,0) -> 1 | C13: =IF('1.3 TF-IDF coseno'!C13>0,1,0) -> 0 | D13: =B13*C13 -> 0
A14: ='1.3 TF-IDF coseno'!A14 -> opportunities | B14: =IF('1.3 TF-IDF coseno'!B14>0,1,0) -> 1 | C14: =IF('1.3 TF-IDF coseno'!C14>0,1,0) -> 0 | D14: =B14*C14 -> 0
A15: ='1.3 TF-IDF coseno'!A15 -> challenges | B15: =IF('1.3 TF-IDF coseno'!B15>0,1,0) -> 1 | C15: =IF('1.3 TF-IDF coseno'!C15>0,1,0) -> 1 | D15: =B15*C15 -> 1
A16: ='1.3 TF-IDF coseno'!A16 -> higher | B16: =IF('1.3 TF-IDF coseno'!B16>0,1,0) -> 1 | C16: =IF('1.3 TF-IDF coseno'!C16>0,1,0) -> 0 | D16: =B16*C16 -> 0
A17: ='1.3 TF-IDF coseno'!A17 -> education | B17: =IF('1.3 TF-IDF coseno'!B17>0,1,0) -> 1 | C17: =IF('1.3 TF-IDF coseno'!C17>0,1,0) -> 1 | D17: =B17*C17 -> 1
A18: ='1.3 TF-IDF coseno'!A18 -> existing | B18: =IF('1.3 TF-IDF coseno'!B18>0,1,0) -> 1 | C18: =IF('1.3 TF-IDF coseno'!C18>0,1,0) -> 0 | D18: =B18*C18 -> 0
A19: ='1.3 TF-IDF coseno'!A19 -> literature | B19: =IF('1.3 TF-IDF coseno'!B19>0,1,0) -> 1 | C19: =IF('1.3 TF-IDF coseno'!C19>0,1,0) -> 0 | D19: =B19*C19 -> 0
A20: ='1.3 TF-IDF coseno'!A20 -> properly | B20: =IF('1.3 TF-IDF coseno'!B20>0,1,0) -> 1 | C20: =IF('1.3 TF-IDF coseno'!C20>0,1,0) -> 0 | D20: =B20*C20 -> 0
A21: ='1.3 TF-IDF coseno'!A21 -> investigated | B21: =IF('1.3 TF-IDF coseno'!B21>0,1,0) -> 1 | C21: =IF('1.3 TF-IDF coseno'!C21>0,1,0) -> 0 | D21: =B21*C21 -> 0
... A147: ='1.3 TF-IDF coseno'!A147 -> fundamental | B147: =IF('1.3 TF-IDF coseno'!B147>0,1,0) -> 0 | C147: =IF('1.3 TF-IDF coseno'!C147>0,1,0) -> 1 | D147: =B147*C147 -> 0

Sheet GloVe vectores
A1: Vectores GloVe (glove-wiki-gigaword-100) de las palabras de los abstracts 11 y 16 · cuenta A y cuenta B = veces que aparece la palabra en cada abstract
A3: Palabra | B3: cuenta A | C3: cuenta B | D3: d1 | E3: d2 | F3: d3 | G3: d4 | H3: d5 | I3: d6 | J3: d7 | K3: d8 | L3: d9 | M3: d10 | N3: d11 | O3: d12 | P3: d13 | Q3: d14 | R3: d15 | S3: d16 | T3: d17 | U3: d18 | V3: d19 | W3: d20 | X3: d21 | Y3: d22 | Z3: d23 | AA3: d24 | AB3: d25 | AC3: d26 | AD3: d27 | AE3: d28 | AF3: d29 | AG3: d30 | AH3: d31 | AI3: d32 | AJ3: d33 | AK3: d34 | AL3: d35 | AM3: d36 | AN3: d37 | AO3: d38 | AP3: d39 | AQ3: d40 | AR3: d41 | AS3: d42 | AT3: d43 | AU3: d44 | AV3: d45 | AW3: d46 | AX3: d47 | AY3: d48 | AZ3: d49 | BA3: d50 | BB3: d51 | BC3: d52 | BD3: d53 | BE3: d54 | BF3: d55 | BG3: d56 | BH3: d57 | BI3: d58 | BJ3: d59 | BK3: d60 | BL3: d61 | BM3: d62 | BN3: d63 | BO3: d64 | BP3: d65 | BQ3: d66 | BR3: d67 | BS3: d68 | BT3: d69 | BU3: d70 | BV3: d71 | BW3: d72 | BX3: d73 | BY3: d74 | BZ3: d75 | CA3: d76 | CB3: d77 | CC3: d78 | CD3: d79 | CE3: d80 | CF3: d81 | CG3: d82 | CH3: d83 | CI3: d84 | CJ3: d85 | CK3: d86 | CL3: d87 | CM3: d88 | CN3: d89 | CO3: d90 | CP3: d91 | CQ3: d92 | CR3: d93 | CS3: d94 | CT3: d95 | CU3: d96 | CV3: d97 | CW3: d98 | CX3: d99 | CY3: d100
A4: generative | B4: =COUNTIF('1.3 TF-IDF coseno'!$M$10:$M$123,A4) -> 2 | C4: =COUNTIF('1.3 TF-IDF coseno'!$N$10:$N$102,A4) -> 7 | D4: 0.35239 | E4: 0.77988 | F4: 0.15489 | G4: 0.11259 | H4: -0.15905 | I4: 0.27251 | J4: -0.40809 | K4: -0.72692 | L4: 0.11867 | M4: 0.18027 | N4: -0.6841 | O4: 0.76745 | P4: -0.048246 | Q4: 0.57617 | R4: 0.64573 | S4: 0.19839 | T4: -0.45937 | U4: 0.79898 | V4: 1.2163 | W4: -0.708 | X4: -0.38933 | Y4: -0.76558 | Z4: 0.63064 | AA4: -0.27196 | AB4: 0.23798 | AC4: -0.41747 | AD4: 0.33256 | AE4: 0.061651 | AF4: -0.10204 | AG4: 0.66058 | AH4: -0.56434 | AI4: 0.19412 | AJ4: -0.16805 | AK4: -0.91181 | AL4: -0.075913 | AM4: -0.16567 | AN4: -0.1862 | AO4: 0.42456 | AP4: -0.93952 | AQ4: -1.3663 | AR4: 0.38085 | AS4: 0.25965 | AT4: -0.2055 | AU4: 0.59215 | AV4: -0.70678 | AW4: 0.40846 | AX4: -0.116 | AY4: 0.0039168 | AZ4: 0.065516 | BA4: 0.93922 | BB4: -0.12103 | BC4: 0.037132 | BD4: 0.39928 | BE4: -0.74498 | BF4: -0.16596 | BG4: 0.45701 | BH4: -0.17093 | BI4: -0.89102 | BJ4: -0.43618 | BK4: -0.053019 | BL4: 0.502 | BM4: -0.31475 | BN4: -1.029 | BO4: 0.34296 | BP4: 0.76058 | BQ4: 0.023688 | BR4: -0.58827 | BS4: 0.0096552 | BT4: 0.55192 | BU4: -0.23178 | BV4: -0.22511 | BW4: 0.015229 | BX4: 0.1328 | BY4: -0.016894 | BZ4: -0.44029 | CA4: -0.38795 | CB4: 0.64377 | CC4: 0.57362 | CD4: 0.018416 | CE4: -0.085088 | CF4: -0.45457 | CG4: 0.47465 | CH4: 0.22805 | CI4: 0.11104 | CJ4: -0.65214 | CK4: 0.89736 | CL4: 0.86518 | CM4: 0.12856 | CN4: -0.15918 | CO4: -0.40459 | CP4: 0.024764 | CQ4: 0.13741 | CR4: 0.22429 | CS4: -0.1663 | CT4: 0.33716 | CU4: -0.69514 | CV4: -0.022794 | CW4: -1.0914 | CX4: 0.80467 | CY4: 1.012
A5: artificial | B5: =COUNTIF('1.3 TF-IDF coseno'!$M$10:$M$123,A5) -> 2 | C5: =COUNTIF('1.3 TF-IDF coseno'!$N$10:$N$102,A5) -> 1 | D5: 0.34547 | E5: 0.31444 | F5: -0.031311 | G5: 0.63676 | H5: 0.27265 | I5: -0.61974 | J5: -0.51774 | K5: -0.2368 | L5: -0.016551 | M5: 0.034353 | N5: -0.15422 | O5: 0.043481 | P5: 0.72984 | Q5: 0.11122 | R5: 1.343 | S5: 0.30638 | T5: 0.13065 | U5: 0.94327 | V5: 0.59695 | W5: -0.3927 | X5: -0.93333 | Y5: 0.60884 | Z5: 0.40629 | AA5: 0.20508 | AB5: 0.037983 | AC5: 0.79005 | AD5: -0.49057 | AE5: -0.73495 | AF5: -0.42249 | AG5: 0.22605 | AH5: 0.028285 | AI5: -0.06285 | AJ5: -0.030594 | AK5: -0.31255 | AL5: 0.11552 | AM5: -0.21525 | AN5: -0.586 | AO5: 1.0774 | AP5: -0.36998 | AQ5: -0.13504 | AR5: -0.075997 | AS5: 0.10737 | AT5: -0.52318 | AU5: -0.2741 | AV5: 0.15267 | AW5: 0.029012 | AX5: -0.1334 | AY5: 0.4277 | AZ5: -0.72453 | BA5: 0.038834 | BB5: -0.33083 | BC5: -0.033361 | BD5: 0.82193 | BE5: 0.3142 | BF5: 0.44183 | BG5: -1.6826 | BH5: 0.25512 | BI5: -0.0073721 | BJ5: 0.6932 | BK5: 0.2951 | BL5: 0.25394 | BM5: 0.63108 | BN5: 0.072754 | BO5: 0.37056 | BP5: 0.70195 | BQ5: -0.20587 | BR5: -0.081056 | BS5: -0.98862 | BT5: -0.30614 | BU5: -1.0855 | BV5: -0.033047 | BW5: 0.29546 | BX5: 0.51402 | BY5: 0.33626 | BZ5: 0.2015 | CA5: 0.01031 | CB5: 0.79075 | CC5: 0.076796 | CD5: -0.2405 | CE5: 0.75816 | CF5: 0.63534 | CG5: -0.40973 | CH5: -0.63246 | CI5: 1.0055 | CJ5: -1.4537 | CK5: 1.0159 | CL5: 1.1268 | CM5: 0.79828 | CN5: 0.21882 | CO5: 0.24361 | CP5: 0.48333 | CQ5: -0.03308 | CR5: -0.25713 | CS5: 0.065248 | CT5: 0.3149 | CU5: -0.34215 | CV5: -0.80395 | CW5: -0.70771 | CX5: 0.76983 | CY5: -0.087996
A6: intelligence | B6: =COUNTIF('1.3 TF-IDF coseno'!$M$10:$M$123,A6) -> 2 | C6: =COUNTIF('1.3 TF-IDF coseno'!$N$10:$N$102,A6) -> 1 | D6: -0.31101 | E6: -0.43291 | F6: 0.77734 | G6: -0.31115 | H6: 0.052934 | I6: -0.8502 | J6: -0.35372 | K6: -0.70531 | L6: 0.084464 | M6: 0.88768 | N6: 0.83527 | O6: -0.41641 | P6: 0.36703 | Q6: 0.60834 | R6: 0.0085214 | S6: 0.94293 | T6: 0.5314 | U6: -0.75322 | V6: -0.86764 | W6: 0.34833 | X6: -0.29865 | Y6: -0.43442 | Z6: 0.3514 | AA6: -1.1228 | AB6: -1.2564 | AC6: -0.094171 | AD6: 0.29402 | AE6: 0.31994 | AF6: 0.086692 | AG6: 0.31915 | AH6: 0.56067 | AI6: 0.032952 | AJ6: -0.94379 | AK6: -0.58112 | AL6: 0.11274 | AM6: 0.006062 | AN6: -0.79353 | AO6: 0.70368 | AP6: 0.59687 | AQ6: 0.60501 | AR6: -0.22855 | AS6: -0.26469 | AT6: 0.045172 | AU6: 0.58118 | AV6: 0.26756 | AW6: -0.47237 | AX6: 0.29358 | AY6: -0.28342 | AZ6: -0.22823 | BA6: -0.59532 | BB6: 1.0845 | BC6: 0.21541 | BD6: 0.5789 | BE6: 1.5825 | BF6: 0.15322 | BG6: -1.3246 | BH6: 0.42594 | BI6: -0.24834 | BJ6: 1.3285 | BK6: 0.48737 | BL6: 0.17115 | BM6: 0.73042 | BN6: 0.51749 | BO6: -0.50172 | BP6: 0.23246 | BQ6: -0.33179 | BR6: -0.31772 | BS6: 0.34714 | BT6: 0.95887 | BU6: 1.5972 | BV6: 0.76459 | BW6: -0.1559 | BX6: -0.13554 | BY6: -0.97654 | BZ6: -0.29545 | CA6: 0.097254 | CB6: -0.17109 | CC6: 0.17695 | CD6: -1.1941 | CE6: 0.41086 | CF6: 1.0578 | CG6: 0.55551 | CH6: 0.034317 | CI6: -0.18596 | CJ6: -1.7366 | CK6: 0.22696 | CL6: 1.0213 | CM6: 0.80212 | CN6: -0.017432 | CO6: -0.45574 | CP6: -0.11358 | CQ6: 0.032074 | CR6: -0.37083 | CS6: 0.22161 | CT6: -0.0030162 | CU6: 0.23286 | CV6: 0.16984 | CW6: -1.0727 | CX6: -0.18416 | CY6: 0.45819
A7: provides | B7: =COUNTIF('1.3 TF-IDF coseno'!$M$10:$M$123,A7) -> 1 | C7: =COUNTIF('1.3 TF-IDF coseno'!$N$10:$N$102,A7) -> 0 | D7: -0.39901 | E7: 0.72219 | F7: 0.35761 | G7: 0.44202 | H7: 0.96065 | I7: -0.14992 | J7: -0.39474 | K7: 0.60111 | L7: -0.0069838 | M7: -0.58195 | N7: 0.38573 | O7: -0.62358 | P7: 0.09346 | Q7: 0.11159 | R7: 0.40168 | S7: -0.028122 | T7: 0.42026 | U7: -0.33642 | V7: 0.057942 | W7: 0.72631 | X7: -0.68665 | Y7: -0.43124 | Z7: -0.0045034 | AA7: -0.33352 | AB7: -0.28637 | AC7: -0.36417 | AD7: -0.24758 | AE7: -0.029707 | AF7: -1.0744 | AG7: -0.21185 | AH7: -0.52507 | AI7: 1.2239 | AJ7: -0.54441 | AK7: 0.031635 | AL7: 0.34985 | AM7: 0.17616 | AN7: -0.15284 | AO7: 0.23009 | AP7: -0.24221 | AQ7: 0.16406 | AR7: 0.072349 | AS7: -0.0056697 | AT7: -0.061041 | AU7: -0.20472 | AV7: 0.10003 | AW7: -0.19559 | AX7: -0.091668 | AY7: -0.2126 | AZ7: 0.096877 | BA7: 0.079562 | BB7: 0.029542 | BC7: -0.11805 | BD7: -0.25408 | BE7: 0.59386 | BF7: 0.055854 | BG7: -2.0044 | BH7: 0.79315 | BI7: -1.0467 | BJ7: 2.0948 | BK7: -0.093772 | BL7: 0.050717 | BM7: -0.19329 | BN7: 0.28786 | BO7: -0.37746 | BP7: 0.67984 | BQ7: -0.14231 | BR7: -0.23934 | BS7: -0.20855 | BT7: 0.61959 | BU7: 0.098884 | BV7: -0.046714 | BW7: -0.18852 | BX7: 0.47946 | BY7: 0.031469 | BZ7: 1.0589 | CA7: 0.20633 | CB7: 0.53744 | CC7: -0.068317 | CD7: -0.92857 | CE7: -0.5814 | CF7: 0.46425 | CG7: 0.0070906 | CH7: -0.55615 | CI7: -0.14932 | CJ7: -1.0091 | CK7: 0.54039 | CL7: 0.54576 | CM7: -0.12443 | CN7: 0.30695 | CO7: 0.39566 | CP7: 0.39365 | CQ7: -0.11755 | CR7: 0.19302 | CS7: -0.51727 | CT7: 0.26023 | CU7: 0.26808 | CV7: 0.1873 | CW7: -0.69134 | CX7: 0.78147 | CY7: 0.75188
A8: opportunities | B8: =COUNTIF('1.3 TF-IDF coseno'!$M$10:$M$123,A8) -> 1 | C8: =COUNTIF('1.3 TF-IDF coseno'!$N$10:$N$102,A8) -> 0 | D8: 0.24241 | E8: 0.45846 | F8: -0.29419 | G8: 0.48428 | H8: 0.70585 | I8: -0.92999 | J8: -0.51084 | K8: 0.004797 | L8: 0.052998 | M8: -0.60376 | N8: 0.032246 | O8: -0.092365 | P8: -0.29923 | Q8: -0.46016 | R8: 0.28315 | S8: -0.43575 | T8: -0.2538 | U8: 0.43662 | V8: -0.9151 | W8: 0.56403 | X8: -0.64571 | Y8: 0.10816 | Z8: -0.12087 | AA8: 0.032933 | AB8: -0.49366 | AC8: -0.44691 | AD8: 0.32416 | AE8: -0.15993 | AF8: -0.59858 | AG8: -0.34355 | AH8: -0.98357 | AI8: 0.83512 | AJ8: -0.28589 | AK8: -0.57337 | AL8: 0.35843 | AM8: -0.44298 | AN8: -0.57896 | AO8: 0.44098 | AP8: -0.78221 | AQ8: -0.11826 | AR8: -0.37672 | AS8: -0.27744 | AT8: -0.3277 | AU8: -0.0054275 | AV8: 0.10801 | AW8: -0.11084 | AX8: 0.39844 | AY8: 0.3028 | AZ8: 0.0053793 | BA8: -0.57754 | BB8: -0.79336 | BC8: 0.10131 | BD8: -1.0414 | BE8: 0.94593 | BF8: 0.80782 | BG8: -1.5309 | BH8: 0.42669 | BI8: -0.59653 | BJ8: 1.5254 | BK8: -0.26122 | BL8: -1.3743 | BM8: 0.46115 | BN8: -0.37133 | BO8: -0.21246 | BP8: 0.2623 | BQ8: -0.083545 | BR8: 0.68394 | BS8: -0.71561 | BT8: 0.73258 | BU8: -0.13596 | BV8: 0.58503 | BW8: -0.28914 | BX8: 0.068506 | BY8: -0.95085 | BZ8: 0.32352 | CA8: 0.52325 | CB8: -0.59789 | CC8: -0.31616 | CD8: -0.13341 | CE8: 0.211 | CF8: 0.55374 | CG8: 0.27205 | CH8: 0.39535 | CI8: -0.28549 | CJ8: -1.4028 | CK8: -0.24287 | CL8: -0.28634 | CM8: 0.045456 | CN8: -0.26317 | CO8: -0.53817 | CP8: -0.58188 | CQ8: -0.39642 | CR8: 0.38452 | CS8: -0.91947 | CT8: -0.65858 | CU8: 0.32465 | CV8: -0.45359 | CW8: 0.15774 | CX8: 0.41552 | CY8: 0.7696
A9: challenges | B9: =COUNTIF('1.3 TF-IDF coseno'!$M$10:$M$123,A9) -> 1 | C9: =COUNTIF('1.3 TF-IDF coseno'!$N$10:$N$102,A9) -> 1 | D9: -0.55188 | E9: 0.72829 | F9: 0.5641 | G9: 0.34889 | H9: 0.35897 | I9: -0.47325 | J9: -0.7506 | K9: -0.51533 | L9: -0.35941 | M9: -0.31772 | N9: -0.027367 | O9: -0.21891 | P9: -0.046079 | Q9: -0.29832 | R9: -0.29427 | S9: -0.52508 | T9: -0.4474 | U9: 0.92838 | V9: -0.81415 | W9: -0.33373 | X9: -0.52969 | Y9: -0.69579 | Z9: 0.11445 | AA9: -0.017317 | AB9: -0.097425 | AC9: 0.10473 | AD9: 0.18007 | AE9: -0.34489 | AF9: -0.36328 | AG9: 0.036613 | AH9: -0.31259 | AI9: -0.33701 | AJ9: 0.20393 | AK9: -0.29402 | AL9: 0.12804 | AM9: -0.23866 | AN9: -0.35718 | AO9: -0.45254 | AP9: -0.056492 | AQ9: 0.11048 | AR9: -1.3352 | AS9: 0.066692 | AT9: 0.36738 | AU9: -0.14631 | AV9: -0.30721 | AW9: 0.1073 | AX9: 0.396 | AY9: 0.089584 | AZ9: -0.48161 | BA9: -0.053925 | BB9: 0.12647 | BC9: -0.3093 | BD9: -0.19711 | BE9: 1.2096 | BF9: 1.3269 | BG9: -1.3543 | BH9: 0.6518 | BI9: -0.19616 | BJ9: 0.82636 | BK9: 0.052784 | BL9: -0.59523 | BM9: 0.21393 | BN9: -0.35276 | BO9: -0.44886 | BP9: 0.79438 | BQ9: -0.046817 | BR9: -0.11141 | BS9: -0.19855 | BT9: 0.064595 | BU9: -0.1332 | BV9: 0.55874 | BW9: 0.25807 | BX9: -0.72467 | BY9: -0.43303 | BZ9: 0.46371 | CA9: -0.057641 | CB9: -0.49447 | CC9: -0.1775 | CD9: -0.53058 | CE9: 0.30308 | CF9: 0.86124 | CG9: -0.36734 | CH9: 0.11124 | CI9: 0.2897 | CJ9: -1.5317 | CK9: -0.53935 | CL9: -0.97646 | CM9: -0.17613 | CN9: -0.53918 | CO9: -0.79721 | CP9: -0.094952 | CQ9: 0.36037 | CR9: -0.12744 | CS9: -0.30829 | CT9: 0.11184 | CU9: 0.69167 | CV9: -0.15503 | CW9: -0.40538 | CX9: 1.2264 | CY9: 0.73299
A10: higher | B10: =COUNTIF('1.3 TF-IDF coseno'!$M$10:$M$123,A10) -> 4 | C10: =COUNTIF('1.3 TF-IDF coseno'!$N$10:$N$102,A10) -> 0 | D10: 0.24193 | E10: 0.67849 | F10: 0.26217 | G10: 0.67969 | H10: -0.12476 | I10: -1.1939 | J10: -1.2223 | K10: -0.14684 | L10: -0.68103 | M10: 0.5827 | N10: -0.19876 | O10: 0.18772 | P10: -0.073993 | Q10: -0.061173 | R10: 0.39389 | S10: -0.86332 | T10: -1.0615 | U10: -0.29955 | V10: 0.19892 | W10: 0.32182 | X10: 0.31248 | Y10: -0.33117 | Z10: 0.018449 | AA10: 0.43362 | AB10: -0.0095435 | AC10: -0.48336 | AD10: 0.29628 | AE10: -1.1735 | AF10: -0.36948 | AG10: 0.26621 | AH10: 0.35377 | AI10: 0.01175 | AJ10: -0.7351 | AK10: -0.033878 | AL10: 0.34104 | AM10: 0.4893 | AN10: -0.02093 | AO10: 0.10017 | AP10: -0.41263 | AQ10: 0.18515 | AR10: -0.071737 | AS10: -0.71521 | AT10: -0.92832 | AU10: -0.46705 | AV10: 0.22142 | AW10: -0.029034 | AX10: 0.30506 | AY10: 0.092585 | AZ10: -0.03231 | BA10: -1.6898 | BB10: 0.074744 | BC10: -0.58399 | BD10: -0.0028272 | BE10: 0.91195 | BF10: -0.37544 | BG10: -1.9169 | BH10: 0.27534 | BI10: -0.45311 | BJ10: 2.6775 | BK10: -0.098016 | BL10: 0.060141 | BM10: 0.12636 | BN10: -0.57272 | BO10: 0.43858 | BP10: -0.3243 | BQ10: 0.01339 | BR10: -0.072263 | BS10: -0.36007 | BT10: 1.2853 | BU10: 0.033994 | BV10: -0.26115 | BW10: -0.14249 | BX10: 0.10828 | BY10: 0.07259 | BZ10: -0.024545 | CA10: 0.16152 | CB10: -0.28274 | CC10: -0.56382 | CD10: -0.4711 | CE10: -0.50271 | CF10: 0.22998 | CG10: 0.32401 | CH10: -1.1461 | CI10: -0.79601 | CJ10: -1.1176 | CK10: -0.74892 | CL10: 0.20702 | CM10: -0.38873 | CN10: 0.26406 | CO10: -0.19047 | CP10: -0.41098 | CQ10: 0.017099 | CR10: -0.70308 | CS10: 0.158 | CT10: -1.0358 | CU10: 0.031633 | CV10: 0.22823 | CW10: -0.26289 | CX10: 0.88606 | CY10: -0.64922
A11: education | B11: =COUNTIF('1.3 TF-IDF coseno'!$M$10:$M$123,A11) -> 4 | C11: =COUNTIF('1.3 TF-IDF coseno'!$N$10:$N$102,A11) -> 2 | D11: 0.29576 | E11: 0.76822 | F11: -0.64301 | G11: 0.3542 | H11: 0.4718 | I11: -0.1886 | J11: -0.4511 | K11: 0.4861 | L11: 0.037184 | M11: 0.89778 | N11: -0.4344 | O11: -0.6782 | P11: -0.52404 | Q11: 0.67126 | R11: 0.051964 | S11: -0.84691 | T11: 0.45369 | U11: 0.038235 | V11: -1.1173 | W11: 0.61603 | X11: -1.1429 | Y11: 0.040068 | Z11: 0.68673 | AA11: -0.099044 | AB11: -0.82311 | AC11: -0.46081 | AD11: 0.21694 | AE11: -0.91177 | AF11: -1.0395 | AG11: 0.1033 | AH11: -0.74415 | AI11: 0.96167 | AJ11: 0.063783 | AK11: 0.038383 | AL11: -0.63326 | AM11: 0.072576 | AN11: -0.96552 | AO11: 0.80286 | AP11: -0.97659 | AQ11: 0.53129 | AR11: -0.60987 | AS11: -0.13728 | AT11: -0.32801 | AU11: -0.09886 | AV11: -0.095179 | AW11: -0.34709 | AX11: 0.32289 | AY11: 0.29248 | AZ11: -0.20091 | BA11: -0.48917 | BB11: -0.071877 | BC11: -0.29989 | BD11: -0.56343 | BE11: 0.78851 | BF11: 0.15249 | BG11: -1.8269 | BH11: 0.91582 | BI11: -0.39346 | BJ11: 2.0874 | BK11: 0.020593 | BL11: 0.28569 | BM11: -0.41762 | BN11: -0.0403 | BO11: -0.5069 | BP11: 0.57702 | BQ11: 0.26037 | BR11: -0.0097665 | BS11: 0.18719 | BT11: 1.4409 | BU11: 0.48926 | BV11: 0.46 | BW11: -0.097184 | BX11: 0.061867 | BY11: -0.37088 | BZ11: -0.25459 | CA11: 0.43804 | CB11: -0.61944 | CC11: 0.40353 | CD11: -0.86386 | CE11: -1.201 | CF11: -0.42141 | CG11: 0.50534 | CH11: 0.091196 | CI11: -0.65938 | CJ11: -1.731 | CK11: 0.50761 | CL11: -0.38395 | CM11: -0.40393 | CN11: -0.08251 | CO11: -0.58137 | CP11: 0.37132 | CQ11: -0.76512 | CR11: -0.070605 | CS11: 0.64349 | CT11: -0.60163 | CU11: 0.14938 | CV11: 0.28977 | CW11: -0.62661 | CX11: 0.5522 | CY11: -0.068743
A12: existing | B12: =COUNTIF('1.3 TF-IDF coseno'!$M$10:$M$123,A12) -> 1 | C12: =COUNTIF('1.3 TF-IDF coseno'!$N$10:$N$102,A12) -> 0 | D12: 0.073762 | E12: 0.32863 | F12: 0.010592 | G12: 0.2834 | H12: -0.10044 | I12: -0.61907 | J12: -0.76746 | K12: 0.11927 | L12: 0.18218 | M12: 0.78544 | N12: 0.14651 | O12: 0.025413 | P12: 0.35077 | Q12: -0.22578 | R12: 0.46994 | S12: -0.84285 | T12: 0.46661 | U12: 0.49999 | V12: 0.068142 | W12: -0.2657 | X12: -0.23393 | Y12: -0.35209 | Z12: 0.47979 | AA12: 0.24575 | AB12: -0.057719 | AC12: -1.1909 | AD12: 0.2117 | AE12: -0.95552 | AF12: -0.58426 | AG12: 0.56775 | AH12: 0.41577 | AI12: 0.80948 | AJ12: -0.21897 | AK12: -0.64616 | AL12: -0.23008 | AM12: 0.38661 | AN12: 0.43897 | AO12: -0.8437 | AP12: -0.41319 | AQ12: -0.044477 | AR12: 0.14951 | AS12: -0.47787 | AT12: 0.1795 | AU12: 0.35893 | AV12: 0.4274 | AW12: 0.50824 | AX12: -0.28022 | AY12: 0.010362 | AZ12: -0.38428 | BA12: -0.38558 | BB12: 0.22059 | BC12: 0.37914 | BD12: -0.068147 | BE12: 0.29043 | BF12: 0.3378 | BG12: -1.6657 | BH12: 0.49844 | BI12: -0.70097 | BJ12: 1.8162 | BK12: 0.10784 | BL12: -0.3033 | BM12: 0.13195 | BN12: 0.19096 | BO12: 0.38976 | BP12: 0.58666 | BQ12: 0.57633 | BR12: -0.2449 | BS12: 0.077876 | BT12: 0.26966 | BU12: -0.54794 | BV12: 0.6725 | BW12: 0.30101 | BX12: 0.35807 | BY12: -0.46903 | BZ12: 0.65306 | CA12: -0.40899 | CB12: -0.018725 | CC12: 0.068953 | CD12: -1.0777 | CE12: 0.13018 | CF12: 0.71381 | CG12: -0.26825 | CH12: 0.070788 | CI12: 0.53845 | CJ12: -1.4113 | CK12: 1.0172 | CL12: -0.079068 | CM12: -0.22278 | CN12: -0.017293 | CO12: 0.65826 | CP12: -0.60836 | CQ12: 0.066255 | CR12: -0.40972 | CS12: -0.58786 | CT12: -0.44147 | CU12: -0.19963 | CV12: -0.14276 | CW12: -0.15333 | CX12: 1.0243 | CY12: 0.47624
A13: literature | B13: =COUNTIF('1.3 TF-IDF coseno'!$M$10:$M$123,A13) -> 1 | C13: =COUNTIF('1.3 TF-IDF coseno'!$N$10:$N$102,A13) -> 0 | D13: 0.28503 | E13: 0.80416 | F13: -0.19562 | G13: 0.71979 | H13: 1.1669 | I13: 0.50556 | J13: 0.24695 | K13: -1.1224 | L13: -0.40798 | M13: 0.377 | N13: -0.78227 | O13: -0.20613 | P13: -0.31861 | Q13: 0.82327 | R13: -0.63337 | S13: 0.28112 | T13: 0.40703 | U13: -0.20191 | V13: 0.0086258 | W13: 0.5585 | X13: -0.51683 | Y13: -0.16477 | Z13: 0.49673 | AA13: -0.21243 | AB13: 0.0025228 | AC13: -0.63552 | AD13: 0.22567 | AE13: -0.75243 | AF13: 0.18837 | AG13: -0.20035 | AH13: -0.87598 | AI13: 0.072468 | AJ13: -0.84329 | AK13: -0.198 | AL13: -0.3244 | AM13: -0.018427 | AN13: -0.63865 | AO13: 0.57961 | AP13: -1.2131 | AQ13: 0.050426 | AR13: -0.98854 | AS13: 0.27221 | AT13: -0.97066 | AU13: -0.28447 | AV13: 0.11899 | AW13: -0.96506 | AX13: 0.64593 | AY13: -0.275 | AZ13: -0.091021 | BA13: 0.37778 | BB13: 0.8973 | BC13: 0.53188 | BD13: 0.63449 | BE13: 0.34218 | BF13: -0.49693 | BG13: -1.0754 | BH13: -0.41038 | BI13: 0.10435 | BJ13: 0.95883 | BK13: 0.17484 | BL13: 0.067505 | BM13: 1.4263 | BN13: -0.43348 | BO13: -0.53848 | BP13: 0.88093 | BQ13: 0.013147 | BR13: 0.64924 | BS13: 0.081101 | BT13: 0.83849 | BU13: 0.088919 | BV13: 0.099251 | BW13: 0.73782 | BX13: 0.7403 | BY13: 0.17657 | BZ13: -1.0219 | CA13: 0.40102 | CB13: -0.20379 | CC13: 0.15329 | CD13: -0.90012 | CE13: -0.65746 | CF13: -0.8946 | CG13: -0.023217 | CH13: -0.29988 | CI13: -0.3083 | CJ13: -1.2622 | CK13: 0.41332 | CL13: -0.74572 | CM13: -1.2287 | CN13: 0.16423 | CO13: -0.43918 | CP13: 0.19205 | CQ13: -0.68811 | CR13: 0.32792 | CS13: 0.47319 | CT13: -0.087294 | CU13: 0.3314 | CV13: -0.27924 | CW13: -0.7853 | CX13: 0.33028 | CY13: 0.69559
A14: properly | B14: =COUNTIF('1.3 TF-IDF coseno'!$M$10:$M$123,A14) -> 1 | C14: =COUNTIF('1.3 TF-IDF coseno'!$N$10:$N$102,A14) -> 0 | D14: -0.72778 | E14: 0.0014966 | F14: -0.26363 | G14: 0.29744 | H14: -0.45792 | I14: 0.67171 | J14: -0.1795 | K14: 0.13456 | L14: 0.51117 | M14: 0.10595 | N14: 0.37352 | O14: 0.22011 | P14: 1.2038 | Q14: 0.18638 | R14: -0.53893 | S14: -0.81158 | T14: 0.31678 | U14: 0.79218 | V14: -0.82943 | W14: -0.94989 | X14: -0.40572 | Y14: -0.63596 | Z14: 0.036332 | AA14: -0.71016 | AB14: -0.7612 | AC14: -0.29572 | AD14: -1.0716 | AE14: -0.17809 | AF14: -0.10064 | AG14: 0.29243 | AH14: 0.28197 | AI14: 0.48215 | AJ14: 0.019815 | AK14: 0.33322 | AL14: 0.63177 | AM14: -0.029153 | AN14: -0.1967 | AO14: -0.30371 | AP14: -0.22438 | AQ14: -0.41432 | AR14: 0.076334 | AS14: -0.43999 | AT14: -0.18223 | AU14: -0.39151 | AV14: -0.49884 | AW14: 0.049789 | AX14: -0.076897 | AY14: -0.46406 | AZ14: -0.5476 | BA14: -1.4495 | BB14: 0.086827 | BC14: -0.15255 | BD14: 0.31607 | BE14: 0.98073 | BF14: -0.25933 | BG14: -0.74564 | BH14: 0.1022 | BI14: -0.044618 | BJ14: 1.3078 | BK14: -0.16488 | BL14: -0.04739 | BM14: 0.64905 | BN14: -0.26571 | BO14: -0.075779 | BP14: 0.56556 | BQ14: -0.13114 | BR14: 0.14195 | BS14: 0.39849 | BT14: 0.13668 | BU14: -0.11201 | BV14: -0.020214 | BW14: 0.13884 | BX14: 0.7741 | BY14: 0.1426 | BZ14: 0.93711 | CA14: -0.065979 | CB14: -0.62063 | CC14: -0.16809 | CD14: -0.2235 | CE14: -0.02518 | CF14: 0.46952 | CG14: 0.20774 | CH14: -0.88015 | CI14: 0.82518 | CJ14: -1.3919 | CK14: -0.12509 | CL14: 0.36848 | CM14: 0.53325 | CN14: -1.1022 | CO14: 0.050293 | CP14: -0.69632 | CQ14: -0.27261 | CR14: -0.27611 | CS14: -0.51208 | CT14: 0.60401 | CU14: 0.44316 | CV14: 0.14461 | CW14: -0.33565 | CX14: 0.081419 | CY14: -0.311
